Workbook

Sheet FINAL
B2: # | C2: Segment · play | D2: Staples path (exact L3/L4) | E2: Score | F2: Primary 1 | G2: Primary 2 | H2: Secondary 1 | I2: Secondary 2 | J2: The story for the room | K2: Commercial moment | L2: Fast-start
B3: 1 | C3: =INDEX('Path Scorecard'!$Q$5:$Q$80,MATCH("CL166388",'Path Scorecard'!$H$5:$H$80,0))&" · "&INDEX('Path Scorecard'!$AC$5:$AC$80,MATCH("CL166388",'Path Scorecard'!$H$5:$H$80,0)) -> Hero · EXTEND | D3: Office Supplies > Calendars & Planners > Planners & Personal Organizers | E3: =INDEX('Path Scorecard'!$Z$5:$Z$80,MATCH("CL166388",'Path Scorecard'!$H$5:$H$80,0)) -> 95 | F3: =INDEX('Path Scorecard'!$AE$5:$AE$80,MATCH("CL166388",'Path Scorecard'!$H$5:$H$80,0)) -> Amazon | G3: =INDEX('Path Scorecard'!$AF$5:$AF$80,MATCH("CL166388",'Path Scorecard'!$H$5:$H$80,0)) -> Target | H3: =INDEX('Path Scorecard'!$AG$5:$AG$80,MATCH("CL166388",'Path Scorecard'!$H$5:$H$80,0)) -> Erin Condren | I3: =INDEX('Path Scorecard'!$AH$5:$AH$80,MATCH("CL166388",'Path Scorecard'!$H$5:$H$80,0)) -> Michaels | J3: Staples launched Sincerely Jules for Blue Sky in Jun-2026. This shows the next step beyond one influencer line. | K3: Jan-2027 New Year planning; Jul-Aug 2027 academic planners. | L3: =INDEX('Path Scorecard'!$AD$5:$AD$80,MATCH("CL166388",'Path Scorecard'!$H$5:$H$80,0)) -> Yes
B4: 2 | C4: =INDEX('Path Scorecard'!$Q$5:$Q$80,MATCH("CL140991",'Path Scorecard'!$H$5:$H$80,0))&" · "&INDEX('Path Scorecard'!$AC$5:$AC$80,MATCH("CL140991",'Path Scorecard'!$H$5:$H$80,0)) -> Hero · EXTEND | D4: Office Supplies > Desk Organizers & Accessories > Desk Organizers | E4: =INDEX('Path Scorecard'!$Z$5:$Z$80,MATCH("CL140991",'Path Scorecard'!$H$5:$H$80,0)) -> 91 | F4: =INDEX('Path Scorecard'!$AE$5:$AE$80,MATCH("CL140991",'Path Scorecard'!$H$5:$H$80,0)) -> Target | G4: =INDEX('Path Scorecard'!$AF$5:$AF$80,MATCH("CL140991",'Path Scorecard'!$H$5:$H$80,0)) -> Amazon | H4: =INDEX('Path Scorecard'!$AG$5:$AG$80,MATCH("CL140991",'Path Scorecard'!$H$5:$H$80,0)) -> Grovemade | I4: =INDEX('Path Scorecard'!$AH$5:$AH$80,MATCH("CL140991",'Path Scorecard'!$H$5:$H$80,0)) -> The Container Store | J4: Desk organization is a header-nav Staples staple and a low-ticket attach to every paper and pen basket. | K4: January 'get organized' season; BTS desk & dorm refresh. | L4: =INDEX('Path Scorecard'!$AD$5:$AD$80,MATCH("CL140991",'Path Scorecard'!$H$5:$H$80,0))
B5: 3 | C5: =INDEX('Path Scorecard'!$Q$5:$Q$80,MATCH("CL142745",'Path Scorecard'!$H$5:$H$80,0))&" · "&INDEX('Path Scorecard'!$AC$5:$AC$80,MATCH("CL142745",'Path Scorecard'!$H$5:$H$80,0)) -> Hero · EXTEND | D5: Bags, Backpacks & Luggage > Backpacks & Laptop Bags > Backpacks | E5: =INDEX('Path Scorecard'!$Z$5:$Z$80,MATCH("CL142745",'Path Scorecard'!$H$5:$H$80,0)) -> 86 | F5: =INDEX('Path Scorecard'!$AE$5:$AE$80,MATCH("CL142745",'Path Scorecard'!$H$5:$H$80,0)) -> Amazon | G5: =INDEX('Path Scorecard'!$AF$5:$AF$80,MATCH("CL142745",'Path Scorecard'!$H$5:$H$80,0)) -> Target | H5: =INDEX('Path Scorecard'!$AG$5:$AG$80,MATCH("CL142745",'Path Scorecard'!$H$5:$H$80,0)) -> Bellroy | I5: =INDEX('Path Scorecard'!$AH$5:$AH$80,MATCH("CL142745",'Path Scorecard'!$H$5:$H$80,0)) -> Urban Outfitters | J5: JanSport now sells on Target Plus, the curated-marketplace peer Pat can point to. | K5: BTS-2027. | L5: =INDEX('Path Scorecard'!$AD$5:$AD$80,MATCH("CL142745",'Path Scorecard'!$H$5:$H$80,0)) -> Yes
B6: 4 | C6: =INDEX('Path Scorecard'!$Q$5:$Q$80,MATCH("CL210795",'Path Scorecard'!$H$5:$H$80,0))&" · "&INDEX('Path Scorecard'!$AC$5:$AC$80,MATCH("CL210795",'Path Scorecard'!$H$5:$H$80,0)) -> Hero · EXTEND | D6: Furniture > Desks > Office Desks | E6: =INDEX('Path Scorecard'!$Z$5:$Z$80,MATCH("CL210795",'Path Scorecard'!$H$5:$H$80,0)) -> 81 | F6: =INDEX('Path Scorecard'!$AE$5:$AE$80,MATCH("CL210795",'Path Scorecard'!$H$5:$H$80,0)) -> Wayfair | G6: =INDEX('Path Scorecard'!$AF$5:$AF$80,MATCH("CL210795",'Path Scorecard'!$H$5:$H$80,0)) -> Amazon | H6: =INDEX('Path Scorecard'!$AG$5:$AG$80,MATCH("CL210795",'Path Scorecard'!$H$5:$H$80,0)) -> Design Within Reach | I6: =INDEX('Path Scorecard'!$AH$5:$AH$80,MATCH("CL210795",'Path Scorecard'!$H$5:$H$80,0)) -> West Elm | J6: Second half of the White Chair story. | K6: Q1 office refresh. | L6: =INDEX('Path Scorecard'!$AD$5:$AD$80,MATCH("CL210795",'Path Scorecard'!$H$5:$H$80,0)) -> Yes
B7: 5 | C7: =INDEX('Path Scorecard'!$Q$5:$Q$80,MATCH("CL354650",'Path Scorecard'!$H$5:$H$80,0))&" · "&INDEX('Path Scorecard'!$AC$5:$AC$80,MATCH("CL354650",'Path Scorecard'!$H$5:$H$80,0)) -> Probable Hero · BUILD | D7: Coffee, Water & Snacks > Water & Beverages > Water Bottles, Tumblers & Travel Mugs | E7: =INDEX('Path Scorecard'!$Z$5:$Z$80,MATCH("CL354650",'Path Scorecard'!$H$5:$H$80,0)) -> 91 | F7: =INDEX('Path Scorecard'!$AE$5:$AE$80,MATCH("CL354650",'Path Scorecard'!$H$5:$H$80,0)) -> Dick's Sporting Goods | G7: =INDEX('Path Scorecard'!$AF$5:$AF$80,MATCH("CL354650",'Path Scorecard'!$H$5:$H$80,0)) -> Target | H7: =INDEX('Path Scorecard'!$AG$5:$AG$80,MATCH("CL354650",'Path Scorecard'!$H$5:$H$80,0)) -> Scheels | I7: =INDEX('Path Scorecard'!$AH$5:$AH$80,MATCH("CL354650",'Path Scorecard'!$H$5:$H$80,0)) -> YETI | J7: Everyone in the room knows the Stanley / Owala craze. | K7: BTS-2027 (Jul-Sep); Q4 gifting; January hydration resolutions. | L7: =INDEX('Path Scorecard'!$AD$5:$AD$80,MATCH("CL354650",'Path Scorecard'!$H$5:$H$80,0)) -> Yes
B8: 6 | C8: =INDEX('Path Scorecard'!$Q$5:$Q$80,MATCH("CL70203",'Path Scorecard'!$H$5:$H$80,0))&" · "&INDEX('Path Scorecard'!$AC$5:$AC$80,MATCH("CL70203",'Path Scorecard'!$H$5:$H$80,0)) -> Probable Hero · BUILD | D8: Furniture > Chairs & Seating > Accent & Waiting Room Chairs | E8: =INDEX('Path Scorecard'!$Z$5:$Z$80,MATCH("CL70203",'Path Scorecard'!$H$5:$H$80,0)) -> 89 | F8: =INDEX('Path Scorecard'!$AE$5:$AE$80,MATCH("CL70203",'Path Scorecard'!$H$5:$H$80,0)) -> Wayfair | G8: =INDEX('Path Scorecard'!$AF$5:$AF$80,MATCH("CL70203",'Path Scorecard'!$H$5:$H$80,0)) -> Amazon | H8: =INDEX('Path Scorecard'!$AG$5:$AG$80,MATCH("CL70203",'Path Scorecard'!$H$5:$H$80,0)) -> Article | I8: =INDEX('Path Scorecard'!$AH$5:$AH$80,MATCH("CL70203",'Path Scorecard'!$H$5:$H$80,0)) -> West Elm | J8: Pat's own example: the thesis in one picture. | K8: Q1-2027 office refresh and return-to-office budgets. | L8: =INDEX('Path Scorecard'!$AD$5:$AD$80,MATCH("CL70203",'Path Scorecard'!$H$5:$H$80,0)) -> Yes
B9: 7 | C9: =INDEX('Path Scorecard'!$Q$5:$Q$80,MATCH("CL167867",'Path Scorecard'!$H$5:$H$80,0))&" · "&INDEX('Path Scorecard'!$AC$5:$AC$80,MATCH("CL167867",'Path Scorecard'!$H$5:$H$80,0)) -> Probable Hero · BUILD | D9: Furniture > Lamps & Lighting > Desk Lamps | E9: =INDEX('Path Scorecard'!$Z$5:$Z$80,MATCH("CL167867",'Path Scorecard'!$H$5:$H$80,0)) -> 86 | F9: =INDEX('Path Scorecard'!$AE$5:$AE$80,MATCH("CL167867",'Path Scorecard'!$H$5:$H$80,0)) -> Wayfair | G9: =INDEX('Path Scorecard'!$AF$5:$AF$80,MATCH("CL167867",'Path Scorecard'!$H$5:$H$80,0)) -> Amazon | H9: =INDEX('Path Scorecard'!$AG$5:$AG$80,MATCH("CL167867",'Path Scorecard'!$H$5:$H$80,0)) -> Lamps Plus | I9: =INDEX('Path Scorecard'!$AH$5:$AH$80,MATCH("CL167867",'Path Scorecard'!$H$5:$H$80,0)) -> Urban Outfitters | J9: 2026 home-office trend reports all name better lighting and warm materials. | K9: Q1-2027 home-office refresh; BTS dorm. | L9: =INDEX('Path Scorecard'!$AD$5:$AD$80,MATCH("CL167867",'Path Scorecard'!$H$5:$H$80,0)) -> Yes
B10: 8 | C10: Probable Hero · BUILD | D10: Bags, Backpacks & Luggage > Totes & Handbags > Lunch Bags & Boxes | E10: 86 | F10: Amazon | G10: Target | H10: Bentgo | I10: Pottery Barn Kids | J10: BTS is Pat's named seasonal anchor and lunch is on every parent's list. | K10: BTS-2027; January 'bring lunch to the office' resolutions. | L10: Yes
B11: 9 | C11: Non-Hero · EXPLORE | D11: Furniture > Decor > Clocks & Timers | E11: 77 | F11: Wayfair | G11: Amazon | H11: Schoolhouse | I11: Anthropologie | J11: Every office wall has one. | K11: Q1 office refresh.
B12: 10 | C12: Non-Hero · EXPLORE | D12: Office Supplies > Desk Organizers & Accessories > Desk Pads | E12: 76 | F12: Amazon | G12: Wayfair | H12: Grovemade | I12: Orbitkey | J12: Wayfair even has a Desk Pads node. | K12: Q1.
B13: 11 | C13: Non-Hero · EXPLORE | D13: Coffee, Water & Snacks > Coffee, Coffee Makers & Supplies > Coffee Organizers & Dispensers | E13: 72 | F13: Amazon | G13: Wayfair | H13: Williams Sonoma | I13: Crate & Barrel | J13: Every office has a coffee corner. | K13: Q1-2027 breakroom refresh; holiday hosting.
B14: 12 | C14: Non-Hero · EXPLORE | D14: Furniture > Cubicle & Panel Systems > Office Partitions & Dividers | E14: 67 | F14: Wayfair | G14: Amazon | H14: Felt Right | I14: Anthropologie | J14: 'Broken-plan' offices and home work corners. | K14: Q1-2027 office fit-outs; WFH corners.

Sheet Executive Summary
A1: Staples Marketplace PoC: the Top 20 L3/L4 shelves, and who to benchmark them against
A2: v3, prepared 29-Sep-2026 for Sai (LatentView). Paths are exact nodes from the Staples navigation tree (snapshot 21-Sep-2026).
A4: • | B4: Recommendation: 20 L3/L4 shelves: 7 Hero, 7 Probable Hero and 6 Non-Hero. Each is benchmarked against 4 competitors: 2 primaries (broad retailers that measure the gap) and 2 secondaries (enthusiast / design specialists outside Staples' scope that show the 'super-extension', like Scheels and Michaels in Ben's examples).
A5: • | B5: Hero = Staples' own top categories (EXTEND with style variants; PROTECT where variants would copy 1P). Probable Hero = the market's top categories where Staples is not yet a destination (BUILD). Non-Hero = neither (EXPLORE: a low-risk test where sellers hold the stock). Full rules and 1-5 anchors are in 'Hero Criteria'.
A6: • | B6: How the 20 are chosen: 4 hard gates, then the Hero segment, then an 8-criterion path score. The best shelves inside each segment fill the quota. Quotas, cut-offs and weights are editable, and everything recalculates.
A7: • | B7: Secondaries double as a recruitment list: 9 of the Top-20 secondary picks are D2C brands that could list on Staples Marketplace themselves (Bellroy, Bentgo, Erin Condren, Fellow, Felt Right, Grovemade, Keychron, Orbitkey, YETI).
A8: • | B8: 8 Top-20 shelves already have Staples SKUs in hand ('Fast-start'); the rest need a Staples leaf scrape first.
A9: • | B9: Caveats: no internal Staples sales or margin data, so 'Hero' uses external proxies (swap in Staples' own sales rank when Pat shares it). Competitor depth is scored from desk research (retailer sites blocked live counts); confirm it when listings are collected.
A11: Top 20 (grouped by segment; everything in this table is live)
A12: # | B12: Segment · play | C12: Staples path (exact L3/L4) | D12: Score | E12: Primary 1 | F12: Primary 2 | G12: Secondary 1 | H12: Secondary 2 | I12: The story for the room | J12: Commercial moment | K12: Fast-start
A13: 1 | B13: =INDEX('Path Scorecard'!$Q$5:$Q$80,MATCH("CL166388",'Path Scorecard'!$H$5:$H$80,0))&" · "&INDEX('Path Scorecard'!$AC$5:$AC$80,MATCH("CL166388",'Path Scorecard'!$H$5:$H$80,0)) -> Hero · EXTEND | C13: Office Supplies > Calendars & Planners > Planners & Personal Organizers | D13: =INDEX('Path Scorecard'!$Z$5:$Z$80,MATCH("CL166388",'Path Scorecard'!$H$5:$H$80,0)) -> 95 | E13: =INDEX('Path Scorecard'!$AE$5:$AE$80,MATCH("CL166388",'Path Scorecard'!$H$5:$H$80,0)) -> Amazon | F13: =INDEX('Path Scorecard'!$AF$5:$AF$80,MATCH("CL166388",'Path Scorecard'!$H$5:$H$80,0)) -> Target | G13: =INDEX('Path Scorecard'!$AG$5:$AG$80,MATCH("CL166388",'Path Scorecard'!$H$5:$H$80,0)) -> Erin Condren | H13: =INDEX('Path Scorecard'!$AH$5:$AH$80,MATCH("CL166388",'Path Scorecard'!$H$5:$H$80,0)) -> Michaels | I13: Staples launched Sincerely Jules for Blue Sky in Jun-2026. This shows the next step beyond one influencer line. | J13: Jan-2027 New Year planning; Jul-Aug 2027 academic planners. | K13: =INDEX('Path Scorecard'!$AD$5:$AD$80,MATCH("CL166388",'Path Scorecard'!$H$5:$H$80,0)) -> Yes
A14: 2 | B14: =INDEX('Path Scorecard'!$Q$5:$Q$80,MATCH("CL140991",'Path Scorecard'!$H$5:$H$80,0))&" · "&INDEX('Path Scorecard'!$AC$5:$AC$80,MATCH("CL140991",'Path Scorecard'!$H$5:$H$80,0)) -> Hero · EXTEND | C14: Office Supplies > Desk Organizers & Accessories > Desk Organizers | D14: =INDEX('Path Scorecard'!$Z$5:$Z$80,MATCH("CL140991",'Path Scorecard'!$H$5:$H$80,0)) -> 91 | E14: =INDEX('Path Scorecard'!$AE$5:$AE$80,MATCH("CL140991",'Path Scorecard'!$H$5:$H$80,0)) -> Target | F14: =INDEX('Path Scorecard'!$AF$5:$AF$80,MATCH("CL140991",'Path Scorecard'!$H$5:$H$80,0)) -> Amazon | G14: =INDEX('Path Scorecard'!$AG$5:$AG$80,MATCH("CL140991",'Path Scorecard'!$H$5:$H$80,0)) -> Grovemade | H14: =INDEX('Path Scorecard'!$AH$5:$AH$80,MATCH("CL140991",'Path Scorecard'!$H$5:$H$80,0)) -> The Container Store | I14: Desk organization is a header-nav Staples staple and a low-ticket attach to every paper and pen basket. | J14: January 'get organized' season; BTS desk & dorm refresh. | K14: =INDEX('Path Scorecard'!$AD$5:$AD$80,MATCH("CL140991",'Path Scorecard'!$H$5:$H$80,0))
A15: 3 | B15: =INDEX('Path Scorecard'!$Q$5:$Q$80,MATCH("CL219245",'Path Scorecard'!$H$5:$H$80,0))&" · "&INDEX('Path Scorecard'!$AC$5:$AC$80,MATCH("CL219245",'Path Scorecard'!$H$5:$H$80,0)) -> Hero · EXTEND | C15: School Supplies > Teacher Supplies > Classroom Decorations > Decorative Accents & Board Sets | D15: =INDEX('Path Scorecard'!$Z$5:$Z$80,MATCH("CL219245",'Path Scorecard'!$H$5:$H$80,0)) -> 86 | E15: =INDEX('Path Scorecard'!$AE$5:$AE$80,MATCH("CL219245",'Path Scorecard'!$H$5:$H$80,0)) -> Amazon | F15: =INDEX('Path Scorecard'!$AF$5:$AF$80,MATCH("CL219245",'Path Scorecard'!$H$5:$H$80,0)) -> Walmart | G15: =INDEX('Path Scorecard'!$AG$5:$AG$80,MATCH("CL219245",'Path Scorecard'!$H$5:$H$80,0)) -> Etsy | H15: =INDEX('Path Scorecard'!$AH$5:$AH$80,MATCH("CL219245",'Path Scorecard'!$H$5:$H$80,0)) -> Oriental Trading | I15: Teachers are a Staples loyalty segment (teacher coupon, teacher lists). | J15: BTS-2027 classroom set-up (Jul-Aug); Teacher Appreciation Week (May). | K15: =INDEX('Path Scorecard'!$AD$5:$AD$80,MATCH("CL219245",'Path Scorecard'!$H$5:$H$80,0))
A16: 4 | B16: =INDEX('Path Scorecard'!$Q$5:$Q$80,MATCH("CL142745",'Path Scorecard'!$H$5:$H$80,0))&" · "&INDEX('Path Scorecard'!$AC$5:$AC$80,MATCH("CL142745",'Path Scorecard'!$H$5:$H$80,0)) -> Hero · EXTEND | C16: Bags, Backpacks & Luggage > Backpacks & Laptop Bags > Backpacks | D16: =INDEX('Path Scorecard'!$Z$5:$Z$80,MATCH("CL142745",'Path Scorecard'!$H$5:$H$80,0)) -> 86 | E16: =INDEX('Path Scorecard'!$AE$5:$AE$80,MATCH("CL142745",'Path Scorecard'!$H$5:$H$80,0)) -> Amazon | F16: =INDEX('Path Scorecard'!$AF$5:$AF$80,MATCH("CL142745",'Path Scorecard'!$H$5:$H$80,0)) -> Target | G16: =INDEX('Path Scorecard'!$AG$5:$AG$80,MATCH("CL142745",'Path Scorecard'!$H$5:$H$80,0)) -> Bellroy | H16: =INDEX('Path Scorecard'!$AH$5:$AH$80,MATCH("CL142745",'Path Scorecard'!$H$5:$H$80,0)) -> Urban Outfitters | I16: JanSport now sells on Target Plus, the curated-marketplace peer Pat can point to. | J16: BTS-2027. | K16: =INDEX('Path Scorecard'!$AD$5:$AD$80,MATCH("CL142745",'Path Scorecard'!$H$5:$H$80,0)) -> Yes
A17: 5 | B17: =INDEX('Path Scorecard'!$Q$5:$Q$80,MATCH("CL210795",'Path Scorecard'!$H$5:$H$80,0))&" · "&INDEX('Path Scorecard'!$AC$5:$AC$80,MATCH("CL210795",'Path Scorecard'!$H$5:$H$80,0)) -> Hero · EXTEND | C17: Furniture > Desks > Office Desks | D17: =INDEX('Path Scorecard'!$Z$5:$Z$80,MATCH("CL210795",'Path Scorecard'!$H$5:$H$80,0)) -> 81 | E17: =INDEX('Path Scorecard'!$AE$5:$AE$80,MATCH("CL210795",'Path Scorecard'!$H$5:$H$80,0)) -> Wayfair | F17: =INDEX('Path Scorecard'!$AF$5:$AF$80,MATCH("CL210795",'Path Scorecard'!$H$5:$H$80,0)) -> Amazon | G17: =INDEX('Path Scorecard'!$AG$5:$AG$80,MATCH("CL210795",'Path Scorecard'!$H$5:$H$80,0)) -> Design Within Reach | H17: =INDEX('Path Scorecard'!$AH$5:$AH$80,MATCH("CL210795",'Path Scorecard'!$H$5:$H$80,0)) -> West Elm | I17: Second half of the White Chair story. | J17: Q1 office refresh. | K17: =INDEX('Path Scorecard'!$AD$5:$AD$80,MATCH("CL210795",'Path Scorecard'!$H$5:$H$80,0)) -> Yes
A18: 6 | B18: =INDEX('Path Scorecard'!$Q$5:$Q$80,MATCH("CL142403",'Path Scorecard'!$H$5:$H$80,0))&" · "&INDEX('Path Scorecard'!$AC$5:$AC$80,MATCH("CL142403",'Path Scorecard'!$H$5:$H$80,0)) -> Hero · EXTEND | C18: Furniture > Boards & Easels > Bulletin Boards | D18: =INDEX('Path Scorecard'!$Z$5:$Z$80,MATCH("CL142403",'Path Scorecard'!$H$5:$H$80,0)) -> 77 | E18: =INDEX('Path Scorecard'!$AE$5:$AE$80,MATCH("CL142403",'Path Scorecard'!$H$5:$H$80,0)) -> Amazon | F18: =INDEX('Path Scorecard'!$AF$5:$AF$80,MATCH("CL142403",'Path Scorecard'!$H$5:$H$80,0)) -> Wayfair | G18: =INDEX('Path Scorecard'!$AG$5:$AG$80,MATCH("CL142403",'Path Scorecard'!$H$5:$H$80,0)) -> Etsy | H18: =INDEX('Path Scorecard'!$AH$5:$AH$80,MATCH("CL142403",'Path Scorecard'!$H$5:$H$80,0)) -> Pottery Barn Teen | I18: Letter boards are an office & classroom staple. | J18: BTS dorm; Jan planning. | K18: =INDEX('Path Scorecard'!$AD$5:$AD$80,MATCH("CL142403",'Path Scorecard'!$H$5:$H$80,0))
A19: 7 | B19: =INDEX('Path Scorecard'!$Q$5:$Q$80,MATCH("CL215783",'Path Scorecard'!$H$5:$H$80,0))&" · "&INDEX('Path Scorecard'!$AC$5:$AC$80,MATCH("CL215783",'Path Scorecard'!$H$5:$H$80,0)) -> Hero · EXTEND | C19: Computers & Accessories > Computer Accessories & Peripherals > Computer Keyboards | D19: =INDEX('Path Scorecard'!$Z$5:$Z$80,MATCH("CL215783",'Path Scorecard'!$H$5:$H$80,0)) -> 75 | E19: =INDEX('Path Scorecard'!$AE$5:$AE$80,MATCH("CL215783",'Path Scorecard'!$H$5:$H$80,0)) -> Amazon | F19: =INDEX('Path Scorecard'!$AF$5:$AF$80,MATCH("CL215783",'Path Scorecard'!$H$5:$H$80,0)) -> Best Buy | G19: =INDEX('Path Scorecard'!$AG$5:$AG$80,MATCH("CL215783",'Path Scorecard'!$H$5:$H$80,0)) -> Keychron | H19: =INDEX('Path Scorecard'!$AH$5:$AH$80,MATCH("CL215783",'Path Scorecard'!$H$5:$H$80,0)) -> Drop | I19: Shows the colour gap inside a brand Staples already sells. | J19: BTS; holiday. | K19: =INDEX('Path Scorecard'!$AD$5:$AD$80,MATCH("CL215783",'Path Scorecard'!$H$5:$H$80,0))
A20: 8 | B20: =INDEX('Path Scorecard'!$Q$5:$Q$80,MATCH("CL354650",'Path Scorecard'!$H$5:$H$80,0))&" · "&INDEX('Path Scorecard'!$AC$5:$AC$80,MATCH("CL354650",'Path Scorecard'!$H$5:$H$80,0)) -> Probable Hero · BUILD | C20: Coffee, Water & Snacks > Water & Beverages > Water Bottles, Tumblers & Travel Mugs | D20: =INDEX('Path Scorecard'!$Z$5:$Z$80,MATCH("CL354650",'Path Scorecard'!$H$5:$H$80,0)) -> 91 | E20: =INDEX('Path Scorecard'!$AE$5:$AE$80,MATCH("CL354650",'Path Scorecard'!$H$5:$H$80,0)) -> Dick's Sporting Goods | F20: =INDEX('Path Scorecard'!$AF$5:$AF$80,MATCH("CL354650",'Path Scorecard'!$H$5:$H$80,0)) -> Target | G20: =INDEX('Path Scorecard'!$AG$5:$AG$80,MATCH("CL354650",'Path Scorecard'!$H$5:$H$80,0)) -> Scheels | H20: =INDEX('Path Scorecard'!$AH$5:$AH$80,MATCH("CL354650",'Path Scorecard'!$H$5:$H$80,0)) -> YETI | I20: Everyone in the room knows the Stanley / Owala craze. | J20: BTS-2027 (Jul-Sep); Q4 gifting; January hydration resolutions. | K20: =INDEX('Path Scorecard'!$AD$5:$AD$80,MATCH("CL354650",'Path Scorecard'!$H$5:$H$80,0)) -> Yes
A21: 9 | B21: =INDEX('Path Scorecard'!$Q$5:$Q$80,MATCH("CL70203",'Path Scorecard'!$H$5:$H$80,0))&" · "&INDEX('Path Scorecard'!$AC$5:$AC$80,MATCH("CL70203",'Path Scorecard'!$H$5:$H$80,0)) -> Probable Hero · BUILD | C21: Furniture > Chairs & Seating > Accent & Waiting Room Chairs | D21: =INDEX('Path Scorecard'!$Z$5:$Z$80,MATCH("CL70203",'Path Scorecard'!$H$5:$H$80,0)) -> 89 | E21: =INDEX('Path Scorecard'!$AE$5:$AE$80,MATCH("CL70203",'Path Scorecard'!$H$5:$H$80,0)) -> Wayfair | F21: =INDEX('Path Scorecard'!$AF$5:$AF$80,MATCH("CL70203",'Path Scorecard'!$H$5:$H$80,0)) -> Amazon | G21: =INDEX('Path Scorecard'!$AG$5:$AG$80,MATCH("CL70203",'Path Scorecard'!$H$5:$H$80,0)) -> Article | H21: =INDEX('Path Scorecard'!$AH$5:$AH$80,MATCH("CL70203",'Path Scorecard'!$H$5:$H$80,0)) -> West Elm | I21: Pat's own example: the thesis in one picture. | J21: Q1-2027 office refresh and return-to-office budgets. | K21: =INDEX('Path Scorecard'!$AD$5:$AD$80,MATCH("CL70203",'Path Scorecard'!$H$5:$H$80,0)) -> Yes
A22: 10 | B22: =INDEX('Path Scorecard'!$Q$5:$Q$80,MATCH("CL167867",'Path Scorecard'!$H$5:$H$80,0))&" · "&INDEX('Path Scorecard'!$AC$5:$AC$80,MATCH("CL167867",'Path Scorecard'!$H$5:$H$80,0)) -> Probable Hero · BUILD | C22: Furniture > Lamps & Lighting > Desk Lamps | D22: =INDEX('Path Scorecard'!$Z$5:$Z$80,MATCH("CL167867",'Path Scorecard'!$H$5:$H$80,0)) -> 86 | E22: =INDEX('Path Scorecard'!$AE$5:$AE$80,MATCH("CL167867",'Path Scorecard'!$H$5:$H$80,0)) -> Wayfair | F22: =INDEX('Path Scorecard'!$AF$5:$AF$80,MATCH("CL167867",'Path Scorecard'!$H$5:$H$80,0)) -> Amazon | G22: =INDEX('Path Scorecard'!$AG$5:$AG$80,MATCH("CL167867",'Path Scorecard'!$H$5:$H$80,0)) -> Lamps Plus | H22: =INDEX('Path Scorecard'!$AH$5:$AH$80,MATCH("CL167867",'Path Scorecard'!$H$5:$H$80,0)) -> Urban Outfitters | I22: 2026 home-office trend reports all name better lighting and warm materials. | J22: Q1-2027 home-office refresh; BTS dorm. | K22: =INDEX('Path Scorecard'!$AD$5:$AD$80,MATCH("CL167867",'Path Scorecard'!$H$5:$H$80,0)) -> Yes
A23: 11 | B23: =INDEX('Path Scorecard'!$Q$5:$Q$80,MATCH("CL141253",'Path Scorecard'!$H$5:$H$80,0))&" · "&INDEX('Path Scorecard'!$AC$5:$AC$80,MATCH("CL141253",'Path Scorecard'!$H$5:$H$80,0)) -> Probable Hero · BUILD | C23: Office Supplies > Writing Supplies & Instruments > Pencil Accessories > Pencil Cases & Pouches | D23: =INDEX('Path Scorecard'!$Z$5:$Z$80,MATCH("CL141253",'Path Scorecard'!$H$5:$H$80,0)) -> 86 | E23: =INDEX('Path Scorecard'!$AE$5:$AE$80,MATCH("CL141253",'Path Scorecard'!$H$5:$H$80,0)) -> Amazon | F23: =INDEX('Path Scorecard'!$AF$5:$AF$80,MATCH("CL141253",'Path Scorecard'!$H$5:$H$80,0)) -> Target | G23: =INDEX('Path Scorecard'!$AG$5:$AG$80,MATCH("CL141253",'Path Scorecard'!$H$5:$H$80,0)) -> JetPens | H23: =INDEX('Path Scorecard'!$AH$5:$AH$80,MATCH("CL141253",'Path Scorecard'!$H$5:$H$80,0)) -> Kinokuniya | I23: Staples' Recess Club / Jellygram exclusives (BTS 2026) already prove the demand. | J23: BTS-2027 (Jul-Sep). | K23: =INDEX('Path Scorecard'!$AD$5:$AD$80,MATCH("CL141253",'Path Scorecard'!$H$5:$H$80,0))
A24: 12 | B24: =INDEX('Path Scorecard'!$Q$5:$Q$80,MATCH("CL165124",'Path Scorecard'!$H$5:$H$80,0))&" · "&INDEX('Path Scorecard'!$AC$5:$AC$80,MATCH("CL165124",'Path Scorecard'!$H$5:$H$80,0)) -> Probable Hero · BUILD | C24: Bags, Backpacks & Luggage > Totes & Handbags > Lunch Bags & Boxes | D24: =INDEX('Path Scorecard'!$Z$5:$Z$80,MATCH("CL165124",'Path Scorecard'!$H$5:$H$80,0)) -> 86 | E24: =INDEX('Path Scorecard'!$AE$5:$AE$80,MATCH("CL165124",'Path Scorecard'!$H$5:$H$80,0)) -> Amazon | F24: =INDEX('Path Scorecard'!$AF$5:$AF$80,MATCH("CL165124",'Path Scorecard'!$H$5:$H$80,0)) -> Target | G24: =INDEX('Path Scorecard'!$AG$5:$AG$80,MATCH("CL165124",'Path Scorecard'!$H$5:$H$80,0)) -> Bentgo | H24: =INDEX('Path Scorecard'!$AH$5:$AH$80,MATCH("CL165124",'Path Scorecard'!$H$5:$H$80,0)) -> Pottery Barn Kids | I24: BTS is Pat's named seasonal anchor and lunch is on every parent's list. | J24: BTS-2027; January 'bring lunch to the office' resolutions. | K24: =INDEX('Path Scorecard'!$AD$5:$AD$80,MATCH("CL165124",'Path Scorecard'!$H$5:$H$80,0)) -> Yes
A25: 13 | B25: =INDEX('Path Scorecard'!$Q$5:$Q$80,MATCH("CL354705",'Path Scorecard'!$H$5:$H$80,0))&" · "&INDEX('Path Scorecard'!$AC$5:$AC$80,MATCH("CL354705",'Path Scorecard'!$H$5:$H$80,0)) -> Probable Hero · BUILD | C25: Office Supplies > Storage & Organization > Storage Baskets | D25: =INDEX('Path Scorecard'!$Z$5:$Z$80,MATCH("CL354705",'Path Scorecard'!$H$5:$H$80,0)) -> 85 | E25: =INDEX('Path Scorecard'!$AE$5:$AE$80,MATCH("CL354705",'Path Scorecard'!$H$5:$H$80,0)) -> Wayfair | F25: =INDEX('Path Scorecard'!$AF$5:$AF$80,MATCH("CL354705",'Path Scorecard'!$H$5:$H$80,0)) -> Target | G25: =INDEX('Path Scorecard'!$AG$5:$AG$80,MATCH("CL354705",'Path Scorecard'!$H$5:$H$80,0)) -> The Container Store | H25: =INDEX('Path Scorecard'!$AH$5:$AH$80,MATCH("CL354705",'Path Scorecard'!$H$5:$H$80,0)) -> Pottery Barn | I25: Organization is a January ritual every retailer promotes. | J25: January 'get organized' season. | K25: =INDEX('Path Scorecard'!$AD$5:$AD$80,MATCH("CL354705",'Path Scorecard'!$H$5:$H$80,0))
A26: 14 | B26: =INDEX('Path Scorecard'!$Q$5:$Q$80,MATCH("CL219256",'Path Scorecard'!$H$5:$H$80,0))&" · "&INDEX('Path Scorecard'!$AC$5:$AC$80,MATCH("CL219256",'Path Scorecard'!$H$5:$H$80,0)) -> Probable Hero · BUILD | C26: Bags, Backpacks & Luggage > Backpacks & Laptop Bags > Laptop Sleeves & Cases | D26: =INDEX('Path Scorecard'!$Z$5:$Z$80,MATCH("CL219256",'Path Scorecard'!$H$5:$H$80,0)) -> 83 | E26: =INDEX('Path Scorecard'!$AE$5:$AE$80,MATCH("CL219256",'Path Scorecard'!$H$5:$H$80,0)) -> Amazon | F26: =INDEX('Path Scorecard'!$AF$5:$AF$80,MATCH("CL219256",'Path Scorecard'!$H$5:$H$80,0)) -> Target | G26: =INDEX('Path Scorecard'!$AG$5:$AG$80,MATCH("CL219256",'Path Scorecard'!$H$5:$H$80,0)) -> Bellroy | H26: =INDEX('Path Scorecard'!$AH$5:$AH$80,MATCH("CL219256",'Path Scorecard'!$H$5:$H$80,0)) -> Urban Outfitters | I26: Directly serves Pat's '1-2 extra items per checkout'. | J26: BTS; laptop-attach all year. | K26: =INDEX('Path Scorecard'!$AD$5:$AD$80,MATCH("CL219256",'Path Scorecard'!$H$5:$H$80,0)) -> Yes
A27: 15 | B27: =INDEX('Path Scorecard'!$Q$5:$Q$80,MATCH("CL161533",'Path Scorecard'!$H$5:$H$80,0))&" · "&INDEX('Path Scorecard'!$AC$5:$AC$80,MATCH("CL161533",'Path Scorecard'!$H$5:$H$80,0)) -> Non-Hero · EXPLORE | C27: Furniture > Decor > Clocks & Timers | D27: =INDEX('Path Scorecard'!$Z$5:$Z$80,MATCH("CL161533",'Path Scorecard'!$H$5:$H$80,0)) -> 77 | E27: =INDEX('Path Scorecard'!$AE$5:$AE$80,MATCH("CL161533",'Path Scorecard'!$H$5:$H$80,0)) -> Wayfair | F27: =INDEX('Path Scorecard'!$AF$5:$AF$80,MATCH("CL161533",'Path Scorecard'!$H$5:$H$80,0)) -> Amazon | G27: =INDEX('Path Scorecard'!$AG$5:$AG$80,MATCH("CL161533",'Path Scorecard'!$H$5:$H$80,0)) -> Schoolhouse | H27: =INDEX('Path Scorecard'!$AH$5:$AH$80,MATCH("CL161533",'Path Scorecard'!$H$5:$H$80,0)) -> Anthropologie | I27: Every office wall has one. | J27: Q1 office refresh. | K27: =INDEX('Path Scorecard'!$AD$5:$AD$80,MATCH("CL161533",'Path Scorecard'!$H$5:$H$80,0))
A28: 16 | B28: =INDEX('Path Scorecard'!$Q$5:$Q$80,MATCH("CL140589",'Path Scorecard'!$H$5:$H$80,0))&" · "&INDEX('Path Scorecard'!$AC$5:$AC$80,MATCH("CL140589",'Path Scorecard'!$H$5:$H$80,0)) -> Non-Hero · EXPLORE | C28: Office Supplies > Desk Organizers & Accessories > Desk Pads | D28: =INDEX('Path Scorecard'!$Z$5:$Z$80,MATCH("CL140589",'Path Scorecard'!$H$5:$H$80,0)) -> 76 | E28: =INDEX('Path Scorecard'!$AE$5:$AE$80,MATCH("CL140589",'Path Scorecard'!$H$5:$H$80,0)) -> Amazon | F28: =INDEX('Path Scorecard'!$AF$5:$AF$80,MATCH("CL140589",'Path Scorecard'!$H$5:$H$80,0)) -> Wayfair | G28: =INDEX('Path Scorecard'!$AG$5:$AG$80,MATCH("CL140589",'Path Scorecard'!$H$5:$H$80,0)) -> Grovemade | H28: =INDEX('Path Scorecard'!$AH$5:$AH$80,MATCH("CL140589",'Path Scorecard'!$H$5:$H$80,0)) -> Orbitkey | I28: Wayfair even has a Desk Pads node. | J28: Q1. | K28: =INDEX('Path Scorecard'!$AD$5:$AD$80,MATCH("CL140589",'Path Scorecard'!$H$5:$H$80,0))
A29: 17 | B29: =INDEX('Path Scorecard'!$Q$5:$Q$80,MATCH("CL214775",'Path Scorecard'!$H$5:$H$80,0))&" · "&INDEX('Path Scorecard'!$AC$5:$AC$80,MATCH("CL214775",'Path Scorecard'!$H$5:$H$80,0)) -> Non-Hero · EXPLORE | C29: Coffee, Water & Snacks > Coffee, Coffee Makers & Supplies > Coffee Organizers & Dispensers | D29: =INDEX('Path Scorecard'!$Z$5:$Z$80,MATCH("CL214775",'Path Scorecard'!$H$5:$H$80,0)) -> 72 | E29: =INDEX('Path Scorecard'!$AE$5:$AE$80,MATCH("CL214775",'Path Scorecard'!$H$5:$H$80,0)) -> Amazon | F29: =INDEX('Path Scorecard'!$AF$5:$AF$80,MATCH("CL214775",'Path Scorecard'!$H$5:$H$80,0)) -> Wayfair | G29: =INDEX('Path Scorecard'!$AG$5:$AG$80,MATCH("CL214775",'Path Scorecard'!$H$5:$H$80,0)) -> Williams Sonoma | H29: =INDEX('Path Scorecard'!$AH$5:$AH$80,MATCH("CL214775",'Path Scorecard'!$H$5:$H$80,0)) -> Crate & Barrel | I29: Every office has a coffee corner. | J29: Q1-2027 breakroom refresh; holiday hosting. | K29: =INDEX('Path Scorecard'!$AD$5:$AD$80,MATCH("CL214775",'Path Scorecard'!$H$5:$H$80,0))
A30: 18 | B30: =INDEX('Path Scorecard'!$Q$5:$Q$80,MATCH("CL166381",'Path Scorecard'!$H$5:$H$80,0))&" · "&INDEX('Path Scorecard'!$AC$5:$AC$80,MATCH("CL166381",'Path Scorecard'!$H$5:$H$80,0)) -> Non-Hero · EXPLORE | C30: Furniture > Cubicle & Panel Systems > Desktop Privacy Panels | D30: =INDEX('Path Scorecard'!$Z$5:$Z$80,MATCH("CL166381",'Path Scorecard'!$H$5:$H$80,0)) -> 69 | E30: =INDEX('Path Scorecard'!$AE$5:$AE$80,MATCH("CL166381",'Path Scorecard'!$H$5:$H$80,0)) -> Amazon | F30: =INDEX('Path Scorecard'!$AF$5:$AF$80,MATCH("CL166381",'Path Scorecard'!$H$5:$H$80,0)) -> Wayfair | G30: =INDEX('Path Scorecard'!$AG$5:$AG$80,MATCH("CL166381",'Path Scorecard'!$H$5:$H$80,0)) -> Felt Right | H30: =INDEX('Path Scorecard'!$AH$5:$AH$80,MATCH("CL166381",'Path Scorecard'!$H$5:$H$80,0)) -> Etsy | I30: Open-plan noise is every office manager's complaint. | J30: Q1-2027 return-to-office fit-outs. | K30: =INDEX('Path Scorecard'!$AD$5:$AD$80,MATCH("CL166381",'Path Scorecard'!$H$5:$H$80,0))
A31: 19 | B31: =INDEX('Path Scorecard'!$Q$5:$Q$80,MATCH("CL70600",'Path Scorecard'!$H$5:$H$80,0))&" · "&INDEX('Path Scorecard'!$AC$5:$AC$80,MATCH("CL70600",'Path Scorecard'!$H$5:$H$80,0)) -> Non-Hero · EXPLORE | C31: Furniture > Cubicle & Panel Systems > Office Partitions & Dividers | D31: =INDEX('Path Scorecard'!$Z$5:$Z$80,MATCH("CL70600",'Path Scorecard'!$H$5:$H$80,0)) -> 67 | E31: =INDEX('Path Scorecard'!$AE$5:$AE$80,MATCH("CL70600",'Path Scorecard'!$H$5:$H$80,0)) -> Wayfair | F31: =INDEX('Path Scorecard'!$AF$5:$AF$80,MATCH("CL70600",'Path Scorecard'!$H$5:$H$80,0)) -> Amazon | G31: =INDEX('Path Scorecard'!$AG$5:$AG$80,MATCH("CL70600",'Path Scorecard'!$H$5:$H$80,0)) -> Felt Right | H31: =INDEX('Path Scorecard'!$AH$5:$AH$80,MATCH("CL70600",'Path Scorecard'!$H$5:$H$80,0)) -> Anthropologie | I31: 'Broken-plan' offices and home work corners. | J31: Q1-2027 office fit-outs; WFH corners. | K31: =INDEX('Path Scorecard'!$AD$5:$AD$80,MATCH("CL70600",'Path Scorecard'!$H$5:$H$80,0))
A32: 20 | B32: =INDEX('Path Scorecard'!$Q$5:$Q$80,MATCH("CL142180",'Path Scorecard'!$H$5:$H$80,0))&" · "&INDEX('Path Scorecard'!$AC$5:$AC$80,MATCH("CL142180",'Path Scorecard'!$H$5:$H$80,0)) -> Non-Hero · EXPLORE | C32: Coffee, Water & Snacks > Coffee, Coffee Makers & Supplies > Carafes, Kettles & Decanters | D32: =INDEX('Path Scorecard'!$Z$5:$Z$80,MATCH("CL142180",'Path Scorecard'!$H$5:$H$80,0)) -> 67 | E32: =INDEX('Path Scorecard'!$AE$5:$AE$80,MATCH("CL142180",'Path Scorecard'!$H$5:$H$80,0)) -> Amazon | F32: =INDEX('Path Scorecard'!$AF$5:$AF$80,MATCH("CL142180",'Path Scorecard'!$H$5:$H$80,0)) -> Target | G32: =INDEX('Path Scorecard'!$AG$5:$AG$80,MATCH("CL142180",'Path Scorecard'!$H$5:$H$80,0)) -> Fellow | H32: =INDEX('Path Scorecard'!$AH$5:$AH$80,MATCH("CL142180",'Path Scorecard'!$H$5:$H$80,0)) -> Williams Sonoma | I32: Coffee culture at the office. | J32: Q4 gifting; Q1 breakroom refresh. | K32: =INDEX('Path Scorecard'!$AD$5:$AD$80,MATCH("CL142180",'Path Scorecard'!$H$5:$H$80,0))
B33: Top-20 mix (live) | C33: =COUNTIFS('Path Scorecard'!$AB$5:$AB$80,"Recommended",'Path Scorecard'!$Q$5:$Q$80,"Hero")&" Hero · "&COUNTIFS('Path Scorecard'!$AB$5:$AB$80,"Recommended",'Path Scorecard'!$Q$5:$Q$80,"Probable Hero")&" Probable Hero · "&COUNTIFS('Path Scorecard'!$AB$5:$AB$80,"Recommended",'Path Scorecard'!$Q$5:$Q$80,"Non-Hero")&" Non-Hero = "&COUNTIFS('Path Scorecard'!$AB$5:$AB$80,"Recommended")&" shelves" -> 7 Hero · 7 Probable Hero · 6 Non-Hero = 20 shelves
A35: What changed
A36: • | B36: v3 vs v2: the recommendation is now a Top 20 with every segment represented (7 / 7 / 6). Non-Hero shelves are no longer capped; their play is EXPLORE (a low-risk marketplace test). Six Non-Hero shelves enter: Clocks, Desk Pads, Coffee Organizers, Desktop Privacy Panels, Office Partitions and Kettles.
A37: • | B37: v3 vs v2: four competitors per shelf (2 primary + 2 secondary) with separate, documented criteria ('Competitor Criteria'). Scheels and Michaels, your original picks, are kept as secondaries where they score best (Water Bottles; Planners). For Backpacks, Bellroy and Urban Outfitters edge Scheels on adjacency, so Scheels stays an alternate.
A38: • | B38: v3 vs v2: dedicated 'Hero Criteria' sheet with plain-English definitions, the decision rule, 1-5 scoring anchors for every factor, quotas and worked plays.
A39: • | B39: v3 vs v2: 9 new candidate shelves researched (incl. Ben's Scheels examples: yard games, recovery tools, hydration mixes). Outdoor Games is a Non-Hero reserve; the rest are backlog.
A40: • | B40: Versus your initial 9-item list: kept and drilled down Chairs & Seating, Desks, Lamps, Hydration and Planning. Parked Rugs and Labels (no L3/L4 below them), reframed Labels & Packaging to small-business packaging, and refocused Fitness to 'active workstation'. See 'Your List Review'.
A42: Suggested sequencing
A43: 1. | B43: Wave 1a (Staples data in hand): Planners, Backpacks, Office desks, Water bottles, Accent chairs, Desk lamps, Lunch, Laptop sleeves.
A44: 2. | B44: Wave 1b (needs a Staples leaf scrape): Desk organizers, Classroom decor, Bulletin boards, Keyboards, Pencil cases, Storage baskets, Clocks, Desk pads, Coffee organizers, Privacy panels, Partitions, Kettles.
...

Sheet Top 20 Recommendations
A1: Top 20 L3/L4 recommendations: 7 Hero · 7 Probable Hero · 6 Non-Hero, each with 4 competitors
A2: Segment, rank, status, play, score and all four competitors are live lookups. Primary = broad retailer (measures the gap); Secondary = enthusiast / design specialist (the super-extension).
A4: # | B4: Hero segment | C4: Rank in segment | D4: Status (live) | E4: Marketplace play | F4: Path score | G4: Staples path (exact) | H4: Level | I4: Category ID | J4: Staples items | K4: SKUs in hand | L4: Fast-start | M4: Primary 1 | N4: Primary 2 | O4: Secondary 1 (enthusiast) | P4: Secondary 2 (enthusiast) | Q4: What the secondaries show (super-extension) | R4: Why this path | S4: Archetypes we expect to find (hypotheses) | T4: 1P watch-out (cannibalisation) | U4: Commercial moment | V4: Why the room will relate | W4: Where to look on the primaries | X4: Staples URL
A5: 1 | B5: =INDEX('Path Scorecard'!$Q$5:$Q$80,MATCH($I5,'Path Scorecard'!$H$5:$H$80,0)) -> Hero | C5: =INDEX('Path Scorecard'!$AA$5:$AA$80,MATCH($I5,'Path Scorecard'!$H$5:$H$80,0)) -> 1 | D5: =INDEX('Path Scorecard'!$AB$5:$AB$80,MATCH($I5,'Path Scorecard'!$H$5:$H$80,0)) -> Recommended | E5: =INDEX('Path Scorecard'!$AC$5:$AC$80,MATCH($I5,'Path Scorecard'!$H$5:$H$80,0)) -> EXTEND | F5: =INDEX('Path Scorecard'!$Z$5:$Z$80,MATCH($I5,'Path Scorecard'!$H$5:$H$80,0)) -> 95 | G5: Office Supplies > Calendars & Planners > Planners & Personal Organizers | H5: 3 | I5: CL166388 | J5: 1037 | K5: 1016 | L5: =INDEX('Path Scorecard'!$AD$5:$AD$80,MATCH($I5,'Path Scorecard'!$H$5:$H$80,0)) -> Yes | M5: =INDEX('Path Scorecard'!$AE$5:$AE$80,MATCH($I5,'Path Scorecard'!$H$5:$H$80,0)) -> Amazon | N5: =INDEX('Path Scorecard'!$AF$5:$AF$80,MATCH($I5,'Path Scorecard'!$H$5:$H$80,0)) -> Target | O5: =INDEX('Path Scorecard'!$AG$5:$AG$80,MATCH($I5,'Path Scorecard'!$H$5:$H$80,0)) -> Erin Condren | P5: =INDEX('Path Scorecard'!$AH$5:$AH$80,MATCH($I5,'Path Scorecard'!$H$5:$H$80,0)) -> Michaels | Q5: Erin Condren and Michaels show the enthusiast planner system: customisable LifePlanners, disc-bound Happy Planner, stickers and accessories sold as an ecosystem. | R5: Staples' deepest stationery shelf (1,037 items) is dated-planner led (Blue Sky, At-A-Glance). Enthusiast formats (disc-bound, undated, sticker-ready, wellness) live at Michaels and Amazon. | S5: Disc-bound customisable planners; undated goal & wellness planners; pastel/floral teacher & student planners; vegan-leather premium planners ($30-60). | T5: Dated 12-month planners incl. the Sincerely Jules exclusive: add other formats, not look-alikes. | U5: Jan-2027 New Year planning; Jul-Aug 2027 academic planners. | V5: Staples launched Sincerely Jules for Blue Sky in Jun-2026. This shows the next step beyond one influencer line. | W5: Amazon: Planners, Refills & Covers (breadth + recruitable sellers). Michaels: Papercraft > Planners (The Happy Planner + companion accessories); near-tie with Amazon. | X5: https://www.staples.com/Planners-Personal-Organizers/cat_CL166388
A6: 2 | B6: =INDEX('Path Scorecard'!$Q$5:$Q$80,MATCH($I6,'Path Scorecard'!$H$5:$H$80,0)) -> Hero | C6: =INDEX('Path Scorecard'!$AA$5:$AA$80,MATCH($I6,'Path Scorecard'!$H$5:$H$80,0)) -> 2 | D6: =INDEX('Path Scorecard'!$AB$5:$AB$80,MATCH($I6,'Path Scorecard'!$H$5:$H$80,0)) -> Recommended | E6: =INDEX('Path Scorecard'!$AC$5:$AC$80,MATCH($I6,'Path Scorecard'!$H$5:$H$80,0)) -> EXTEND | F6: =INDEX('Path Scorecard'!$Z$5:$Z$80,MATCH($I6,'Path Scorecard'!$H$5:$H$80,0)) -> 91 | G6: Office Supplies > Desk Organizers & Accessories > Desk Organizers | H6: 3 | I6: CL140991 | J6: 342 | K6: 0 | L6: =INDEX('Path Scorecard'!$AD$5:$AD$80,MATCH($I6,'Path Scorecard'!$H$5:$H$80,0)) | M6: =INDEX('Path Scorecard'!$AE$5:$AE$80,MATCH($I6,'Path Scorecard'!$H$5:$H$80,0)) -> Target | N6: =INDEX('Path Scorecard'!$AF$5:$AF$80,MATCH($I6,'Path Scorecard'!$H$5:$H$80,0)) -> Amazon | O6: =INDEX('Path Scorecard'!$AG$5:$AG$80,MATCH($I6,'Path Scorecard'!$H$5:$H$80,0)) -> Grovemade | P6: =INDEX('Path Scorecard'!$AH$5:$AH$80,MATCH($I6,'Path Scorecard'!$H$5:$H$80,0)) -> The Container Store | Q6: Grovemade shows the premium end (walnut, cork, modular desk systems); The Container Store shows coordinated acrylic / marble collections. | R6: Staples' 342 organizers are mostly black mesh and utility. Target (Brightroom) and Container Store sell coordinated desk collections in acrylic, bamboo, marble, linen and pastel. | S6: Clear acrylic modular sets; warm-wood / bamboo sets; pastel & neutral 'aesthetic desk' collections; turntable caddies. | T6: Black mesh sets (Staples brand, Officemate). | U6: January 'get organized' season; BTS desk & dorm refresh. | V6: Desk organization is a header-nav Staples staple and a low-ticket attach to every paper and pen basket. | W6: Target: Brightroom desk organization + Target Plus brands. Amazon: Desk Organizers. Container Store: Office > Desktop Collections (style benchmark). | X6: https://www.staples.com/Desk-Organizers/cat_CL140991
A7: 3 | B7: =INDEX('Path Scorecard'!$Q$5:$Q$80,MATCH($I7,'Path Scorecard'!$H$5:$H$80,0)) -> Hero | C7: =INDEX('Path Scorecard'!$AA$5:$AA$80,MATCH($I7,'Path Scorecard'!$H$5:$H$80,0)) -> 3 | D7: =INDEX('Path Scorecard'!$AB$5:$AB$80,MATCH($I7,'Path Scorecard'!$H$5:$H$80,0)) -> Recommended | E7: =INDEX('Path Scorecard'!$AC$5:$AC$80,MATCH($I7,'Path Scorecard'!$H$5:$H$80,0)) -> EXTEND | F7: =INDEX('Path Scorecard'!$Z$5:$Z$80,MATCH($I7,'Path Scorecard'!$H$5:$H$80,0)) -> 86 | G7: School Supplies > Teacher Supplies > Classroom Decorations > Decorative Accents & Board Sets | H7: 4 | I7: CL219245 | J7: 607 | K7: 0 | L7: =INDEX('Path Scorecard'!$AD$5:$AD$80,MATCH($I7,'Path Scorecard'!$H$5:$H$80,0)) | M7: =INDEX('Path Scorecard'!$AE$5:$AE$80,MATCH($I7,'Path Scorecard'!$H$5:$H$80,0)) -> Amazon | N7: =INDEX('Path Scorecard'!$AF$5:$AF$80,MATCH($I7,'Path Scorecard'!$H$5:$H$80,0)) -> Walmart | O7: =INDEX('Path Scorecard'!$AG$5:$AG$80,MATCH($I7,'Path Scorecard'!$H$5:$H$80,0)) -> Etsy | P7: =INDEX('Path Scorecard'!$AH$5:$AH$80,MATCH($I7,'Path Scorecard'!$H$5:$H$80,0)) -> Oriental Trading | Q7: Etsy shows handmade theme sets (boho, calm); Oriental Trading shows complete themed classroom kits. | R7: 607 Staples items. Teachers self-fund about $895 a year and buy decor as coordinated themes (boho, calm, pastel). | S7: Boho / neutral theme sets; calm-corner & SEL decor; pastel bulletin-board kits; plant & nature themes. | T7: Existing bulletin-board sets: compare theme coverage, not SKU swaps. | U7: BTS-2027 classroom set-up (Jul-Aug); Teacher Appreciation Week (May). | V7: Teachers are a Staples loyalty segment (teacher coupon, teacher lists). | W7: Amazon: Classroom Decorations. Oriental Trading: Teaching Supplies > Classroom Decorations. Michaels: Teacher Supplies. | X7: https://www.staples.com/Decorative-Accents-Board-Sets/cat_CL219245
A8: 4 | B8: =INDEX('Path Scorecard'!$Q$5:$Q$80,MATCH($I8,'Path Scorecard'!$H$5:$H$80,0)) -> Hero | C8: =INDEX('Path Scorecard'!$AA$5:$AA$80,MATCH($I8,'Path Scorecard'!$H$5:$H$80,0)) -> 4 | D8: =INDEX('Path Scorecard'!$AB$5:$AB$80,MATCH($I8,'Path Scorecard'!$H$5:$H$80,0)) -> Recommended | E8: =INDEX('Path Scorecard'!$AC$5:$AC$80,MATCH($I8,'Path Scorecard'!$H$5:$H$80,0)) -> EXTEND | F8: =INDEX('Path Scorecard'!$Z$5:$Z$80,MATCH($I8,'Path Scorecard'!$H$5:$H$80,0)) -> 86 | G8: Bags, Backpacks & Luggage > Backpacks & Laptop Bags > Backpacks | H8: 3 | I8: CL142745 | J8: 585 | K8: 542 | L8: =INDEX('Path Scorecard'!$AD$5:$AD$80,MATCH($I8,'Path Scorecard'!$H$5:$H$80,0)) -> Yes | M8: =INDEX('Path Scorecard'!$AE$5:$AE$80,MATCH($I8,'Path Scorecard'!$H$5:$H$80,0)) -> Amazon | N8: =INDEX('Path Scorecard'!$AF$5:$AF$80,MATCH($I8,'Path Scorecard'!$H$5:$H$80,0)) -> Target | O8: =INDEX('Path Scorecard'!$AG$5:$AG$80,MATCH($I8,'Path Scorecard'!$H$5:$H$80,0)) -> Bellroy | P8: =INDEX('Path Scorecard'!$AH$5:$AH$80,MATCH($I8,'Path Scorecard'!$H$5:$H$80,0)) -> Urban Outfitters | Q8: Bellroy shows premium commuter design; Urban Outfitters shows fashion-led styles (mini packs, corduroy). Scheels and REI (alternates) show technical packs. | R8: 585 Staples items, laptop & commuter led. 85% of parents bought a backpack for BTS; lifestyle backpacks grew 3% in 2025 (Circana). | S8: Corduroy / soft-aesthetic backpacks; Scandinavian-minimal daypacks; mini backpacks; personalisable patch & pin packs. | T8: Laptop backpacks (SwissGear, Targus): watch cannibalisation here. | U8: BTS-2027. | V8: JanSport now sells on Target Plus, the curated-marketplace peer Pat can point to. | W8: Amazon: Backpacks. Target: Backpacks (incl. JanSport on Target Plus). | X8: https://www.staples.com/Backpacks/cat_CL142745
A9: 5 | B9: =INDEX('Path Scorecard'!$Q$5:$Q$80,MATCH($I9,'Path Scorecard'!$H$5:$H$80,0)) -> Hero | C9: =INDEX('Path Scorecard'!$AA$5:$AA$80,MATCH($I9,'Path Scorecard'!$H$5:$H$80,0)) -> 5 | D9: =INDEX('Path Scorecard'!$AB$5:$AB$80,MATCH($I9,'Path Scorecard'!$H$5:$H$80,0)) -> Recommended | E9: =INDEX('Path Scorecard'!$AC$5:$AC$80,MATCH($I9,'Path Scorecard'!$H$5:$H$80,0)) -> EXTEND | F9: =INDEX('Path Scorecard'!$Z$5:$Z$80,MATCH($I9,'Path Scorecard'!$H$5:$H$80,0)) -> 81 | G9: Furniture > Desks > Office Desks | H9: 3 | I9: CL210795 | J9: 1501 | K9: 1265 | L9: =INDEX('Path Scorecard'!$AD$5:$AD$80,MATCH($I9,'Path Scorecard'!$H$5:$H$80,0)) -> Yes | M9: =INDEX('Path Scorecard'!$AE$5:$AE$80,MATCH($I9,'Path Scorecard'!$H$5:$H$80,0)) -> Wayfair | N9: =INDEX('Path Scorecard'!$AF$5:$AF$80,MATCH($I9,'Path Scorecard'!$H$5:$H$80,0)) -> Amazon | O9: =INDEX('Path Scorecard'!$AG$5:$AG$80,MATCH($I9,'Path Scorecard'!$H$5:$H$80,0)) -> Design Within Reach | P9: =INDEX('Path Scorecard'!$AH$5:$AH$80,MATCH($I9,'Path Scorecard'!$H$5:$H$80,0)) -> West Elm | Q9: Design Within Reach shows iconic design desks (Herman Miller); West Elm shows mid-century home-office desks. | R9: 1,501 Staples items. Pilot Computer-desk split: 3 recommended archetypes (1 Strong). Split by Staples' own type facet. | S9: Fluted / curved-edge writing desks; cane & rattan desks; small-space floating desks; warm-wood Scandinavian desks. | T9: Laminate computer desks (Bush, Sauder, Union & Scale). | U9: Q1 office refresh. | V9: Second half of the White Chair story. | W9: Wayfair: Office Furniture > Desks + Small Space Offices. Amazon: Home Office Desks. | X9: https://www.staples.com/Office-Desks/cat_CL210795
A10: 6 | B10: =INDEX('Path Scorecard'!$Q$5:$Q$80,MATCH($I10,'Path Scorecard'!$H$5:$H$80,0)) -> Hero | C10: =INDEX('Path Scorecard'!$AA$5:$AA$80,MATCH($I10,'Path Scorecard'!$H$5:$H$80,0)) -> 6 | D10: =INDEX('Path Scorecard'!$AB$5:$AB$80,MATCH($I10,'Path Scorecard'!$H$5:$H$80,0)) -> Recommended | E10: =INDEX('Path Scorecard'!$AC$5:$AC$80,MATCH($I10,'Path Scorecard'!$H$5:$H$80,0)) -> EXTEND | F10: =INDEX('Path Scorecard'!$Z$5:$Z$80,MATCH($I10,'Path Scorecard'!$H$5:$H$80,0)) -> 77 | G10: Furniture > Boards & Easels > Bulletin Boards | H10: 3 | I10: CL142403 | J10: 284 | K10: 0 | L10: =INDEX('Path Scorecard'!$AD$5:$AD$80,MATCH($I10,'Path Scorecard'!$H$5:$H$80,0)) | M10: =INDEX('Path Scorecard'!$AE$5:$AE$80,MATCH($I10,'Path Scorecard'!$H$5:$H$80,0)) -> Amazon | N10: =INDEX('Path Scorecard'!$AF$5:$AF$80,MATCH($I10,'Path Scorecard'!$H$5:$H$80,0)) -> Wayfair | O10: =INDEX('Path Scorecard'!$AG$5:$AG$80,MATCH($I10,'Path Scorecard'!$H$5:$H$80,0)) -> Etsy | P10: =INDEX('Path Scorecard'!$AH$5:$AH$80,MATCH($I10,'Path Scorecard'!$H$5:$H$80,0)) -> Pottery Barn Teen | Q10: Etsy shows letter boards and custom felt boards; Pottery Barn Teen shows scalloped, fabric and statement pinboards. | R10: 284 Staples items, cork & utility led. | S10: Fabric memo boards; felt letter boards; pinnable felt tiles; framed & acrylic boards. | T10: Cork boards (Quartet, U Brands). | U10: BTS dorm; Jan planning. | V10: Letter boards are an office & classroom staple. | W10: Amazon: memo & letter boards. Wayfair: Office Organization > Memo Boards. | X10: https://www.staples.com/Bulletin-Boards/cat_CL142403
A11: 7 | B11: =INDEX('Path Scorecard'!$Q$5:$Q$80,MATCH($I11,'Path Scorecard'!$H$5:$H$80,0)) -> Hero | C11: =INDEX('Path Scorecard'!$AA$5:$AA$80,MATCH($I11,'Path Scorecard'!$H$5:$H$80,0)) -> 7 | D11: =INDEX('Path Scorecard'!$AB$5:$AB$80,MATCH($I11,'Path Scorecard'!$H$5:$H$80,0)) -> Recommended | E11: =INDEX('Path Scorecard'!$AC$5:$AC$80,MATCH($I11,'Path Scorecard'!$H$5:$H$80,0)) -> EXTEND | F11: =INDEX('Path Scorecard'!$Z$5:$Z$80,MATCH($I11,'Path Scorecard'!$H$5:$H$80,0)) -> 75 | G11: Computers & Accessories > Computer Accessories & Peripherals > Computer Keyboards | H11: 3 | I11: CL215783 | J11: 374 | K11: 0 | L11: =INDEX('Path Scorecard'!$AD$5:$AD$80,MATCH($I11,'Path Scorecard'!$H$5:$H$80,0)) | M11: =INDEX('Path Scorecard'!$AE$5:$AE$80,MATCH($I11,'Path Scorecard'!$H$5:$H$80,0)) -> Amazon | N11: =INDEX('Path Scorecard'!$AF$5:$AF$80,MATCH($I11,'Path Scorecard'!$H$5:$H$80,0)) -> Best Buy | O11: =INDEX('Path Scorecard'!$AG$5:$AG$80,MATCH($I11,'Path Scorecard'!$H$5:$H$80,0)) -> Keychron | P11: =INDEX('Path Scorecard'!$AH$5:$AH$80,MATCH($I11,'Path Scorecard'!$H$5:$H$80,0)) -> Drop | Q11: Keychron and Drop show the enthusiast keyboard world: retro layouts, custom keycaps, hot-swap switches. | R11: 374 Staples items. Typewriter-style and pastel keyboards went mainstream (Logitech POP). | S11: Retro round-key keyboards; pastel compact 75% boards; colour-matched keyboard + mouse sets. | T11: Logitech / Microsoft business keyboards: core 1P, watch CRS. | U11: BTS; holiday. | V11: Shows the colour gap inside a brand Staples already sells. | W11: Amazon: Keyboards. Best Buy: Keyboards (colour filter). | X11: https://www.staples.com/Computer-Keyboards/cat_CL215783
A12: 8 | B12: =INDEX('Path Scorecard'!$Q$5:$Q$80,MATCH($I12,'Path Scorecard'!$H$5:$H$80,0)) -> Probable Hero | C12: =INDEX('Path Scorecard'!$AA$5:$AA$80,MATCH($I12,'Path Scorecard'!$H$5:$H$80,0)) -> 1 | D12: =INDEX('Path Scorecard'!$AB$5:$AB$80,MATCH($I12,'Path Scorecard'!$H$5:$H$80,0)) -> Recommended | E12: =INDEX('Path Scorecard'!$AC$5:$AC$80,MATCH($I12,'Path Scorecard'!$H$5:$H$80,0)) -> BUILD | F12: =INDEX('Path Scorecard'!$Z$5:$Z$80,MATCH($I12,'Path Scorecard'!$H$5:$H$80,0)) -> 91 | G12: Coffee, Water & Snacks > Water & Beverages > Water Bottles, Tumblers & Travel Mugs | H12: 3 | I12: CL354650 | J12: 463 | K12: 462 | L12: =INDEX('Path Scorecard'!$AD$5:$AD$80,MATCH($I12,'Path Scorecard'!$H$5:$H$80,0)) -> Yes | M12: =INDEX('Path Scorecard'!$AE$5:$AE$80,MATCH($I12,'Path Scorecard'!$H$5:$H$80,0)) -> Dick's Sporting Goods | N12: =INDEX('Path Scorecard'!$AF$5:$AF$80,MATCH($I12,'Path Scorecard'!$H$5:$H$80,0)) -> Target | O12: =INDEX('Path Scorecard'!$AG$5:$AG$80,MATCH($I12,'Path Scorecard'!$H$5:$H$80,0)) -> Scheels | P12: =INDEX('Path Scorecard'!$AH$5:$AH$80,MATCH($I12,'Path Scorecard'!$H$5:$H$80,0)) -> YETI | Q12: Scheels shows wall-to-wall colourways, lids and accessories; YETI shows customisation and premium colour drops. | R12: Staples carries 463 desk-use items. Specialists sell full colourways, lids, sizes and accessories from Owala, Stanley, YETI, HydroJug and BruMate. | S12: Sip/chug hybrid bottles; 40 oz handle tumblers in seasonal colourways; kids' 12-16 oz school bottles; lids, boots & straw accessories. | T12: Stanley / Hydro Flask SKUs Staples already sells: gap is colourway & size, not the same SKU. | U12: BTS-2027 (Jul-Sep); Q4 gifting; January hydration resolutions. | V12: Everyone in the room knows the Stanley / Owala craze. | W12: Dick's: Drinkware / Sport Water Bottles. Target: water bottles & tumblers incl. exclusive colourways. | X12: https://www.staples.com/Water-Bottles-Tumblers-Travel-Mugs/cat_CL354650
A13: 9 | B13: =INDEX('Path Scorecard'!$Q$5:$Q$80,MATCH($I13,'Path Scorecard'!$H$5:$H$80,0)) -> Probable Hero | C13: =INDEX('Path Scorecard'!$AA$5:$AA$80,MATCH($I13,'Path Scorecard'!$H$5:$H$80,0)) -> 2 | D13: =INDEX('Path Scorecard'!$AB$5:$AB$80,MATCH($I13,'Path Scorecard'!$H$5:$H$80,0)) -> Recommended | E13: =INDEX('Path Scorecard'!$AC$5:$AC$80,MATCH($I13,'Path Scorecard'!$H$5:$H$80,0)) -> BUILD | F13: =INDEX('Path Scorecard'!$Z$5:$Z$80,MATCH($I13,'Path Scorecard'!$H$5:$H$80,0)) -> 89 | G13: Furniture > Chairs & Seating > Accent & Waiting Room Chairs | H13: 3 | I13: CL70203 | J13: 229 | K13: 199 | L13: =INDEX('Path Scorecard'!$AD$5:$AD$80,MATCH($I13,'Path Scorecard'!$H$5:$H$80,0)) -> Yes | M13: =INDEX('Path Scorecard'!$AE$5:$AE$80,MATCH($I13,'Path Scorecard'!$H$5:$H$80,0)) -> Wayfair | N13: =INDEX('Path Scorecard'!$AF$5:$AF$80,MATCH($I13,'Path Scorecard'!$H$5:$H$80,0)) -> Amazon | O13: =INDEX('Path Scorecard'!$AG$5:$AG$80,MATCH($I13,'Path Scorecard'!$H$5:$H$80,0)) -> Article | P13: =INDEX('Path Scorecard'!$AH$5:$AH$80,MATCH($I13,'Path Scorecard'!$H$5:$H$80,0)) -> West Elm | Q13: Article and West Elm show the design-led mid-century / boucle end at $300-600. | R13: The original 'White Chair' shelf. Pilot (Sep-2026): 5 recommended archetypes, 2 Strong; 94% high-confidence mapping. | S13: Boucle / curved barrel chairs; cream & sage upholstered side chairs with wood legs; rattan & cane lounge chairs; $150-350 design tier. | T13: Black vinyl / fabric guest & reception chairs (Flash, Boss, HON). | U13: Q1-2027 office refresh and return-to-office budgets. | V13: Pat's own example: the thesis in one picture. | W13: Wayfair: Living Room > Accent Chairs and Professional > Office Seating > Accent Chairs. Amazon: Accent Chairs. | X13: https://www.staples.com/Accent-Waiting-Room-Chairs/cat_CL70203
A14: 10 | B14: =INDEX('Path Scorecard'!$Q$5:$Q$80,MATCH($I14,'Path Scorecard'!$H$5:$H$80,0)) -> Probable Hero | C14: =INDEX('Path Scorecard'!$AA$5:$AA$80,MATCH($I14,'Path Scorecard'!$H$5:$H$80,0)) -> 3 | D14: =INDEX('Path Scorecard'!$AB$5:$AB$80,MATCH($I14,'Path Scorecard'!$H$5:$H$80,0)) -> Recommended | E14: =INDEX('Path Scorecard'!$AC$5:$AC$80,MATCH($I14,'Path Scorecard'!$H$5:$H$80,0)) -> BUILD | F14: =INDEX('Path Scorecard'!$Z$5:$Z$80,MATCH($I14,'Path Scorecard'!$H$5:$H$80,0)) -> 86 | G14: Furniture > Lamps & Lighting > Desk Lamps | H14: 3 | I14: CL167867 | J14: 210 | K14: 195 | L14: =INDEX('Path Scorecard'!$AD$5:$AD$80,MATCH($I14,'Path Scorecard'!$H$5:$H$80,0)) -> Yes | M14: =INDEX('Path Scorecard'!$AE$5:$AE$80,MATCH($I14,'Path Scorecard'!$H$5:$H$80,0)) -> Wayfair | N14: =INDEX('Path Scorecard'!$AF$5:$AF$80,MATCH($I14,'Path Scorecard'!$H$5:$H$80,0)) -> Amazon | O14: =INDEX('Path Scorecard'!$AG$5:$AG$80,MATCH($I14,'Path Scorecard'!$H$5:$H$80,0)) -> Lamps Plus | P14: =INDEX('Path Scorecard'!$AH$5:$AH$80,MATCH($I14,'Path Scorecard'!$H$5:$H$80,0)) -> Urban Outfitters | Q14: Lamps Plus shows specialist depth (90,000+ designs); Urban Outfitters shows trend lamps (mushroom, pleated). | R14: 210 Staples items, mostly LED task lamps. Wayfair sells mushroom, pleated, rechargeable and sculptural lamps that sit between task light and decor. | S14: Mushroom / dome lamps; pleated-shade & ceramic-base lamps; rechargeable cordless lamps; brass & warm-wood architect lamps. | T14: LED task lamps with USB ports: Staples' core. | U14: Q1-2027 home-office refresh; BTS dorm. | V14: 2026 home-office trend reports all name better lighting and warm materials. | W14: Wayfair: Lighting > Table & Floor Lamps > Desk Lamps (+ Teen Desk Lamps). Amazon: Desk Lamps. | X14: https://www.staples.com/Desk-Lamps/cat_CL167867
A15: 11 | B15: =INDEX('Path Scorecard'!$Q$5:$Q$80,MATCH($I15,'Path Scorecard'!$H$5:$H$80,0)) -> Probable Hero | C15: =INDEX('Path Scorecard'!$AA$5:$AA$80,MATCH($I15,'Path Scorecard'!$H$5:$H$80,0)) -> 4 | D15: =INDEX('Path Scorecard'!$AB$5:$AB$80,MATCH($I15,'Path Scorecard'!$H$5:$H$80,0)) -> Recommended | E15: =INDEX('Path Scorecard'!$AC$5:$AC$80,MATCH($I15,'Path Scorecard'!$H$5:$H$80,0)) -> BUILD | F15: =INDEX('Path Scorecard'!$Z$5:$Z$80,MATCH($I15,'Path Scorecard'!$H$5:$H$80,0)) -> 86 | G15: Office Supplies > Writing Supplies & Instruments > Pencil Accessories > Pencil Cases & Pouches | H15: 4 | I15: CL141253 | J15: 107 | K15: 0 | L15: =INDEX('Path Scorecard'!$AD$5:$AD$80,MATCH($I15,'Path Scorecard'!$H$5:$H$80,0)) | M15: =INDEX('Path Scorecard'!$AE$5:$AE$80,MATCH($I15,'Path Scorecard'!$H$5:$H$80,0)) -> Amazon | N15: =INDEX('Path Scorecard'!$AF$5:$AF$80,MATCH($I15,'Path Scorecard'!$H$5:$H$80,0)) -> Target | O15: =INDEX('Path Scorecard'!$AG$5:$AG$80,MATCH($I15,'Path Scorecard'!$H$5:$H$80,0)) -> JetPens | P15: =INDEX('Path Scorecard'!$AH$5:$AH$80,MATCH($I15,'Path Scorecard'!$H$5:$H$80,0)) -> Kinokuniya | Q15: JetPens and Kinokuniya show Japanese stationery culture: stand-up pouches, multi-compartment cases, character collabs. | R15: 107 Staples items. The pencil pouch is the first 'aesthetic' purchase in the BTS basket, at under $20. | S15: Large-capacity multi-layer pouches (Japanese style); clear / jelly pouches; corduroy & quilted pouches; kawaii & character cases. | T15: Staples' own Recess Club pouches: extend beyond them, don't duplicate. | U15: BTS-2027 (Jul-Sep). | V15: Staples' Recess Club / Jellygram exclusives (BTS 2026) already prove the demand. | W15: Amazon: Pencil Cases. Target: pencil cases & pouches. JetPens: Pencil Cases (style benchmark). | X15: https://www.staples.com/Pencil-Cases-Pouches/cat_CL141253
A16: 12 | B16: =INDEX('Path Scorecard'!$Q$5:$Q$80,MATCH($I16,'Path Scorecard'!$H$5:$H$80,0)) -> Probable Hero | C16: =INDEX('Path Scorecard'!$AA$5:$AA$80,MATCH($I16,'Path Scorecard'!$H$5:$H$80,0)) -> 5 | D16: =INDEX('Path Scorecard'!$AB$5:$AB$80,MATCH($I16,'Path Scorecard'!$H$5:$H$80,0)) -> Recommended | E16: =INDEX('Path Scorecard'!$AC$5:$AC$80,MATCH($I16,'Path Scorecard'!$H$5:$H$80,0)) -> BUILD | F16: =INDEX('Path Scorecard'!$Z$5:$Z$80,MATCH($I16,'Path Scorecard'!$H$5:$H$80,0)) -> 86 | G16: Bags, Backpacks & Luggage > Totes & Handbags > Lunch Bags & Boxes | H16: 3 | I16: CL165124 | J16: 404 | K16: 406 | L16: =INDEX('Path Scorecard'!$AD$5:$AD$80,MATCH($I16,'Path Scorecard'!$H$5:$H$80,0)) -> Yes | M16: =INDEX('Path Scorecard'!$AE$5:$AE$80,MATCH($I16,'Path Scorecard'!$H$5:$H$80,0)) -> Amazon | N16: =INDEX('Path Scorecard'!$AF$5:$AF$80,MATCH($I16,'Path Scorecard'!$H$5:$H$80,0)) -> Target | O16: =INDEX('Path Scorecard'!$AG$5:$AG$80,MATCH($I16,'Path Scorecard'!$H$5:$H$80,0)) -> Bentgo | P16: =INDEX('Path Scorecard'!$AH$5:$AH$80,MATCH($I16,'Path Scorecard'!$H$5:$H$80,0)) -> Pottery Barn Kids | Q16: Bentgo shows the bento system for kids and adults; Pottery Barn Kids shows personalised, coordinated lunch bundles. | R16: 404 Staples items. Bento compartments, stainless and leak-proof designs lead BTS and work-lunch search. | S16: Bento compartment boxes (kids & adult); neutral / vegan-leather insulated lunch totes; stainless & glass meal-prep sets. | T16: Basic insulated lunch bags Staples already stocks. | U16: BTS-2027; January 'bring lunch to the office' resolutions. | V16: BTS is Pat's named seasonal anchor and lunch is on every parent's list. | W16: Amazon: Lunch Boxes & Bags. Target: lunch boxes & bags (Bentgo, Stasher, owned brands). | X16: https://www.staples.com/Lunch-Bags-Boxes/cat_CL165124
... A24: 20 | B24: =INDEX('Path Scorecard'!$Q$5:$Q$80,MATCH($I24,'Path Scorecard'!$H$5:$H$80,0)) -> Non-Hero | C24: =INDEX('Path Scorecard'!$AA$5:$AA$80,MATCH($I24,'Path Scorecard'!$H$5:$H$80,0)) -> 6 | D24: =INDEX('Path Scorecard'!$AB$5:$AB$80,MATCH($I24,'Path Scorecard'!$H$5:$H$80,0)) -> Recommended | E24: =INDEX('Path Scorecard'!$AC$5:$AC$80,MATCH($I24,'Path Scorecard'!$H$5:$H$80,0)) -> EXPLORE | F24: =INDEX('Path Scorecard'!$Z$5:$Z$80,MATCH($I24,'Path Scorecard'!$H$5:$H$80,0)) -> 67 | G24: Coffee, Water & Snacks > Coffee, Coffee Makers & Supplies > Carafes, Kettles & Decanters | H24: 3 | I24: CL142180 | J24: 55 | K24: 0 | L24: =INDEX('Path Scorecard'!$AD$5:$AD$80,MATCH($I24,'Path Scorecard'!$H$5:$H$80,0)) | M24: =INDEX('Path Scorecard'!$AE$5:$AE$80,MATCH($I24,'Path Scorecard'!$H$5:$H$80,0)) -> Amazon | N24: =INDEX('Path Scorecard'!$AF$5:$AF$80,MATCH($I24,'Path Scorecard'!$H$5:$H$80,0)) -> Target | O24: =INDEX('Path Scorecard'!$AG$5:$AG$80,MATCH($I24,'Path Scorecard'!$H$5:$H$80,0)) -> Fellow | P24: =INDEX('Path Scorecard'!$AH$5:$AH$80,MATCH($I24,'Path Scorecard'!$H$5:$H$80,0)) -> Williams Sonoma | Q24: Fellow and Williams Sonoma show the design / coffee-enthusiast kettle. | R24: 55 Staples items of carafes, kettles & decanters. The gooseneck, temperature-control kettle (Fellow Stagg) is a design object in coffee culture. | S24: Matte-black gooseneck kettles with temperature control; retro enamel kettles; glass tea kettles. | T24: Basic electric kettles and airpots (moderate 1P). | U24: Q4 gifting; Q1 breakroom refresh. | V24: Coffee culture at the office. | W24: Amazon / Target: electric kettles. Fellow: Stagg range. Williams Sonoma: kettles. | X24: https://www.staples.com/Carafes-Kettles-Decanters/cat_CL142180
A26: Reserves: the next 3 shelves per segment (swap-ins)
A27: R1 | B27: =INDEX('Path Scorecard'!$Q$5:$Q$80,MATCH($I27,'Path Scorecard'!$H$5:$H$80,0)) -> Hero | C27: =INDEX('Path Scorecard'!$AA$5:$AA$80,MATCH($I27,'Path Scorecard'!$H$5:$H$80,0)) -> 8 | D27: =INDEX('Path Scorecard'!$AB$5:$AB$80,MATCH($I27,'Path Scorecard'!$H$5:$H$80,0)) -> Reserve | E27: =INDEX('Path Scorecard'!$AC$5:$AC$80,MATCH($I27,'Path Scorecard'!$H$5:$H$80,0)) -> EXTEND | F27: =INDEX('Path Scorecard'!$Z$5:$Z$80,MATCH($I27,'Path Scorecard'!$H$5:$H$80,0)) -> 74 | G27: Office Supplies > Calendars & Planners > Calendars | H27: 3 | I27: CL166389 | J27: 1234 | K27: 0 | L27: =INDEX('Path Scorecard'!$AD$5:$AD$80,MATCH($I27,'Path Scorecard'!$H$5:$H$80,0)) | M27: =INDEX('Path Scorecard'!$AE$5:$AE$80,MATCH($I27,'Path Scorecard'!$H$5:$H$80,0)) -> Amazon | N27: =INDEX('Path Scorecard'!$AF$5:$AF$80,MATCH($I27,'Path Scorecard'!$H$5:$H$80,0)) -> Target | O27: =INDEX('Path Scorecard'!$AG$5:$AG$80,MATCH($I27,'Path Scorecard'!$H$5:$H$80,0)) -> Erin Condren | P27: =INDEX('Path Scorecard'!$AH$5:$AH$80,MATCH($I27,'Path Scorecard'!$H$5:$H$80,0)) -> Etsy | Q27: Erin Condren and Etsy show design and personalised calendars. | R27: 1,234 Staples items of dated wall & desk calendars. | S27: Art & photography wall calendars; acrylic reusable calendars; minimalist desk calendars. | T27: At-A-Glance / Blue Sky dated calendars: core 1P. | U27: Q4-2026 / Jan-2027 dated-goods peak. | V27: Calendar season lines up with Q1 planning. | W27: Amazon: wall calendars. Target. | X27: https://www.staples.com/Calendars/cat_CL166389
