Workbook

Sheet Executive Summary
A1: Staples Marketplace PoC: which L3/L4 shelves to analyse, and against whom
A2: v2, prepared 29-Sep-2026 for Sai (LatentView). Paths are exact nodes from the Staples navigation tree (snapshot 21-Sep-2026).
A4: • | B4: Recommendation: run the PoC on 10 Tier-1 L3/L4 shelves across 5 Staples L1s, benchmarked against 6 competitors. A further 23 Tier-2 shelves are ready as swap-ins.
A5: • | B5: Two lenses, one answer. Lens 1, Hero segmentation: is the shelf a Staples Hero (its own strength), a Probable Hero (a market favourite where Staples is not yet a destination) or a Non-Hero? Lens 2, a path score: 8 criteria led by Pat's 'White Chair' test, competitor depth and 1P protection.
A6: • | B6: Tier 1 mixes both growth stories: 4 Heroes to EXTEND with style variants and 6 Probable Heroes to BUILD with marketplace sellers. Non-Heroes are capped at Tier 3, and Heroes where variants would substitute 1P (Office Chairs, Pens) are marked PROTECT.
A7: • | B7: Every shelf first passed four hard gates: a true L3/L4 in the Staples tree, on Staples' work / school / small-business mission, 20+ Staples items as a baseline, and no clash with a Staples partner (Party City now supplies party décor and gift wrap on Staples.com).
A8: • | B8: Six Tier-1 shelves already have Staples SKUs in hand ('Fast-start'). Competitors are picked per shelf; Amazon wins most secondaries because its sellers are the ones Staples can actually recruit.
A9: • | B9: Caveats: no internal Staples sales or margin data exists, so 'Hero' uses external proxies (depth, header-nav visibility, merchandising investment, shopper association); swap in Staples' own sales rank when Pat shares it. Competitor depth is scored from desk research; confirm it when the listings are collected.
A11: Tier 1: PoC wave 1
A12: # | B12: Staples path (exact L3/L4) | C12: Score | D12: Level | E12: Hero segment · play | F12: Primary competitor | G12: Secondary competitor | H12: The story for the room | I12: Commercial moment | J12: Fast-start
A13: 1 | B13: Office Supplies > Calendars & Planners > Planners & Personal Organizers | C13: =INDEX('Path Scorecard'!$Z$5:$Z$71,MATCH("CL166388",'Path Scorecard'!$H$5:$H$71,0)) -> 95 | D13: L3 | E13: =INDEX('Path Scorecard'!$Q$5:$Q$71,MATCH("CL166388",'Path Scorecard'!$H$5:$H$71,0))&" · "&INDEX('Path Scorecard'!$AC$5:$AC$71,MATCH("CL166388",'Path Scorecard'!$H$5:$H$71,0)) -> Hero · EXTEND | F13: =INDEX('Path Scorecard'!$AE$5:$AE$71,MATCH("CL166388",'Path Scorecard'!$H$5:$H$71,0)) -> Amazon | G13: =INDEX('Path Scorecard'!$AF$5:$AF$71,MATCH("CL166388",'Path Scorecard'!$H$5:$H$71,0)) -> Michaels | H13: Staples launched Sincerely Jules for Blue Sky in Jun-2026. This shows the next step beyond one influencer line. | I13: Jan-2027 New Year planning; Jul-Aug 2027 academic planners. | J13: =INDEX('Path Scorecard'!$AD$5:$AD$71,MATCH("CL166388",'Path Scorecard'!$H$5:$H$71,0)) -> Yes
A14: 2 | B14: Office Supplies > Desk Organizers & Accessories > Desk Organizers | C14: =INDEX('Path Scorecard'!$Z$5:$Z$71,MATCH("CL140991",'Path Scorecard'!$H$5:$H$71,0)) -> 91 | D14: L3 | E14: =INDEX('Path Scorecard'!$Q$5:$Q$71,MATCH("CL140991",'Path Scorecard'!$H$5:$H$71,0))&" · "&INDEX('Path Scorecard'!$AC$5:$AC$71,MATCH("CL140991",'Path Scorecard'!$H$5:$H$71,0)) -> Hero · EXTEND | F14: =INDEX('Path Scorecard'!$AE$5:$AE$71,MATCH("CL140991",'Path Scorecard'!$H$5:$H$71,0)) -> Target | G14: =INDEX('Path Scorecard'!$AF$5:$AF$71,MATCH("CL140991",'Path Scorecard'!$H$5:$H$71,0)) -> Amazon | H14: Desk organization is a header-nav Staples staple and a low-ticket attach to every paper and pen basket. | I14: January 'get organized' season; BTS desk & dorm refresh. | J14: =INDEX('Path Scorecard'!$AD$5:$AD$71,MATCH("CL140991",'Path Scorecard'!$H$5:$H$71,0))
A15: 3 | B15: Coffee, Water & Snacks > Water & Beverages > Water Bottles, Tumblers & Travel Mugs | C15: =INDEX('Path Scorecard'!$Z$5:$Z$71,MATCH("CL354650",'Path Scorecard'!$H$5:$H$71,0)) -> 91 | D15: L3 | E15: =INDEX('Path Scorecard'!$Q$5:$Q$71,MATCH("CL354650",'Path Scorecard'!$H$5:$H$71,0))&" · "&INDEX('Path Scorecard'!$AC$5:$AC$71,MATCH("CL354650",'Path Scorecard'!$H$5:$H$71,0)) -> Probable Hero · BUILD | F15: =INDEX('Path Scorecard'!$AE$5:$AE$71,MATCH("CL354650",'Path Scorecard'!$H$5:$H$71,0)) -> Dick's Sporting Goods | G15: =INDEX('Path Scorecard'!$AF$5:$AF$71,MATCH("CL354650",'Path Scorecard'!$H$5:$H$71,0)) -> Target | H15: Everyone in the room knows the Stanley / Owala craze. | I15: BTS-2027 (Jul-Sep); Q4 gifting; January hydration resolutions. | J15: =INDEX('Path Scorecard'!$AD$5:$AD$71,MATCH("CL354650",'Path Scorecard'!$H$5:$H$71,0)) -> Yes
A16: 4 | B16: Furniture > Chairs & Seating > Accent & Waiting Room Chairs | C16: =INDEX('Path Scorecard'!$Z$5:$Z$71,MATCH("CL70203",'Path Scorecard'!$H$5:$H$71,0)) -> 89 | D16: L3 | E16: =INDEX('Path Scorecard'!$Q$5:$Q$71,MATCH("CL70203",'Path Scorecard'!$H$5:$H$71,0))&" · "&INDEX('Path Scorecard'!$AC$5:$AC$71,MATCH("CL70203",'Path Scorecard'!$H$5:$H$71,0)) -> Probable Hero · BUILD | F16: =INDEX('Path Scorecard'!$AE$5:$AE$71,MATCH("CL70203",'Path Scorecard'!$H$5:$H$71,0)) -> Wayfair | G16: =INDEX('Path Scorecard'!$AF$5:$AF$71,MATCH("CL70203",'Path Scorecard'!$H$5:$H$71,0)) -> Amazon | H16: Pat's own example: the thesis in one picture. | I16: Q1-2027 office refresh and return-to-office budgets. | J16: =INDEX('Path Scorecard'!$AD$5:$AD$71,MATCH("CL70203",'Path Scorecard'!$H$5:$H$71,0)) -> Yes
A17: 5 | B17: Furniture > Lamps & Lighting > Desk Lamps | C17: =INDEX('Path Scorecard'!$Z$5:$Z$71,MATCH("CL167867",'Path Scorecard'!$H$5:$H$71,0)) -> 86 | D17: L3 | E17: =INDEX('Path Scorecard'!$Q$5:$Q$71,MATCH("CL167867",'Path Scorecard'!$H$5:$H$71,0))&" · "&INDEX('Path Scorecard'!$AC$5:$AC$71,MATCH("CL167867",'Path Scorecard'!$H$5:$H$71,0)) -> Probable Hero · BUILD | F17: =INDEX('Path Scorecard'!$AE$5:$AE$71,MATCH("CL167867",'Path Scorecard'!$H$5:$H$71,0)) -> Wayfair | G17: =INDEX('Path Scorecard'!$AF$5:$AF$71,MATCH("CL167867",'Path Scorecard'!$H$5:$H$71,0)) -> Amazon | H17: 2026 home-office trend reports all name better lighting and warm materials. | I17: Q1-2027 home-office refresh; BTS dorm. | J17: =INDEX('Path Scorecard'!$AD$5:$AD$71,MATCH("CL167867",'Path Scorecard'!$H$5:$H$71,0)) -> Yes
A18: 6 | B18: Office Supplies > Writing Supplies & Instruments > Pencil Accessories > Pencil Cases & Pouches | C18: =INDEX('Path Scorecard'!$Z$5:$Z$71,MATCH("CL141253",'Path Scorecard'!$H$5:$H$71,0)) -> 86 | D18: L4 | E18: =INDEX('Path Scorecard'!$Q$5:$Q$71,MATCH("CL141253",'Path Scorecard'!$H$5:$H$71,0))&" · "&INDEX('Path Scorecard'!$AC$5:$AC$71,MATCH("CL141253",'Path Scorecard'!$H$5:$H$71,0)) -> Probable Hero · BUILD | F18: =INDEX('Path Scorecard'!$AE$5:$AE$71,MATCH("CL141253",'Path Scorecard'!$H$5:$H$71,0)) -> Amazon | G18: =INDEX('Path Scorecard'!$AF$5:$AF$71,MATCH("CL141253",'Path Scorecard'!$H$5:$H$71,0)) -> Target | H18: Staples' Recess Club / Jellygram exclusives (BTS 2026) already prove the demand. | I18: BTS-2027 (Jul-Sep). | J18: =INDEX('Path Scorecard'!$AD$5:$AD$71,MATCH("CL141253",'Path Scorecard'!$H$5:$H$71,0))
A19: 7 | B19: Bags, Backpacks & Luggage > Backpacks & Laptop Bags > Backpacks | C19: =INDEX('Path Scorecard'!$Z$5:$Z$71,MATCH("CL142745",'Path Scorecard'!$H$5:$H$71,0)) -> 86 | D19: L3 | E19: =INDEX('Path Scorecard'!$Q$5:$Q$71,MATCH("CL142745",'Path Scorecard'!$H$5:$H$71,0))&" · "&INDEX('Path Scorecard'!$AC$5:$AC$71,MATCH("CL142745",'Path Scorecard'!$H$5:$H$71,0)) -> Hero · EXTEND | F19: =INDEX('Path Scorecard'!$AE$5:$AE$71,MATCH("CL142745",'Path Scorecard'!$H$5:$H$71,0)) -> Amazon | G19: =INDEX('Path Scorecard'!$AF$5:$AF$71,MATCH("CL142745",'Path Scorecard'!$H$5:$H$71,0)) -> Target | H19: JanSport now sells on Target Plus, the curated-marketplace peer Pat can point to. | I19: BTS-2027. | J19: =INDEX('Path Scorecard'!$AD$5:$AD$71,MATCH("CL142745",'Path Scorecard'!$H$5:$H$71,0)) -> Yes
A20: 8 | B20: Bags, Backpacks & Luggage > Totes & Handbags > Lunch Bags & Boxes | C20: =INDEX('Path Scorecard'!$Z$5:$Z$71,MATCH("CL165124",'Path Scorecard'!$H$5:$H$71,0)) -> 86 | D20: L3 | E20: =INDEX('Path Scorecard'!$Q$5:$Q$71,MATCH("CL165124",'Path Scorecard'!$H$5:$H$71,0))&" · "&INDEX('Path Scorecard'!$AC$5:$AC$71,MATCH("CL165124",'Path Scorecard'!$H$5:$H$71,0)) -> Probable Hero · BUILD | F20: =INDEX('Path Scorecard'!$AE$5:$AE$71,MATCH("CL165124",'Path Scorecard'!$H$5:$H$71,0)) -> Amazon | G20: =INDEX('Path Scorecard'!$AF$5:$AF$71,MATCH("CL165124",'Path Scorecard'!$H$5:$H$71,0)) -> Target | H20: BTS is Pat's named seasonal anchor and lunch is on every parent's list. | I20: BTS-2027; January 'bring lunch to the office' resolutions. | J20: =INDEX('Path Scorecard'!$AD$5:$AD$71,MATCH("CL165124",'Path Scorecard'!$H$5:$H$71,0)) -> Yes
A21: 9 | B21: School Supplies > Teacher Supplies > Classroom Decorations > Decorative Accents & Board Sets | C21: =INDEX('Path Scorecard'!$Z$5:$Z$71,MATCH("CL219245",'Path Scorecard'!$H$5:$H$71,0)) -> 86 | D21: L4 | E21: =INDEX('Path Scorecard'!$Q$5:$Q$71,MATCH("CL219245",'Path Scorecard'!$H$5:$H$71,0))&" · "&INDEX('Path Scorecard'!$AC$5:$AC$71,MATCH("CL219245",'Path Scorecard'!$H$5:$H$71,0)) -> Hero · EXTEND | F21: =INDEX('Path Scorecard'!$AE$5:$AE$71,MATCH("CL219245",'Path Scorecard'!$H$5:$H$71,0)) -> Amazon | G21: =INDEX('Path Scorecard'!$AF$5:$AF$71,MATCH("CL219245",'Path Scorecard'!$H$5:$H$71,0)) -> Oriental Trading | H21: Teachers are a Staples loyalty segment (teacher coupon, teacher lists). | I21: BTS-2027 classroom set-up (Jul-Aug); Teacher Appreciation Week (May). | J21: =INDEX('Path Scorecard'!$AD$5:$AD$71,MATCH("CL219245",'Path Scorecard'!$H$5:$H$71,0))
A22: 10 | B22: Office Supplies > Storage & Organization > Storage Baskets | C22: =INDEX('Path Scorecard'!$Z$5:$Z$71,MATCH("CL354705",'Path Scorecard'!$H$5:$H$71,0)) -> 85 | D22: L3 | E22: =INDEX('Path Scorecard'!$Q$5:$Q$71,MATCH("CL354705",'Path Scorecard'!$H$5:$H$71,0))&" · "&INDEX('Path Scorecard'!$AC$5:$AC$71,MATCH("CL354705",'Path Scorecard'!$H$5:$H$71,0)) -> Probable Hero · BUILD | F22: =INDEX('Path Scorecard'!$AE$5:$AE$71,MATCH("CL354705",'Path Scorecard'!$H$5:$H$71,0)) -> Wayfair | G22: =INDEX('Path Scorecard'!$AF$5:$AF$71,MATCH("CL354705",'Path Scorecard'!$H$5:$H$71,0)) -> Target | H22: Organization is a January ritual every retailer promotes. | I22: January 'get organized' season. | J22: =INDEX('Path Scorecard'!$AD$5:$AD$71,MATCH("CL354705",'Path Scorecard'!$H$5:$H$71,0))
B23: Tier-1 mix (live) | C23: =COUNTIFS('Path Scorecard'!$AB$5:$AB$71,"Tier 1",'Path Scorecard'!$Q$5:$Q$71,"Hero")&" Hero · "&COUNTIFS('Path Scorecard'!$AB$5:$AB$71,"Tier 1",'Path Scorecard'!$Q$5:$Q$71,"Probable Hero")&" Probable Hero · "&COUNTIFS('Path Scorecard'!$AB$5:$AB$71,"Tier 1",'Path Scorecard'!$Q$5:$Q$71,"Non-Hero")&" Non-Hero" -> 4 Hero · 6 Probable Hero · 0 Non-Hero
A25: What changed versus the initial 9-item list
A26: • | B26: Kept and drilled down: Chairs & Seating, Desks, Lamps & Lighting (Wayfair stays primary), Hydration (now the exact L3 'Water Bottles, Tumblers & Travel Mugs') and Planning (Planners is the #1 shelf overall).
A27: • | B27: Hero segmentation moved from L2 to L3/L4. Most of the original L2s hold more than one segment: Chairs & Seating has a Hero to protect (Office Chairs), Probable Heroes to build (Accent, Bar Stools, Benches, Breakroom, Ottomans) and Non-Heroes (Kids, Gaming). See 'Your List Review' column I and the roll-up in 'Hero Segmentation'.
A28: • | B28: Competitor changed: Backpacks & Bags moves from Scheels to Amazon + Target (Scheels skews technical / outdoor, away from Staples' student and commuter shopper); Hydration moves to Dick's + Target (same brands as Scheels, national reach).
A29: • | B29: Parked: Rugs (no L3/L4 under 'Decor > Rugs') and Labels (an L2 leaf of commodity labels, and a Staples Hero to protect). Reframed: 'Labels & Packaging' becomes small-business packaging (Retail Boxes & Bags, Mailers, Label Makers vs Amazon + Uline); gift wrap and gift bags are gated out because of the Party City partnership.
A30: • | B30: Refocused: Fitness becomes an 'active workstation' idea (walking pads next to sit-stand desks); a Probable Hero, but Tier 3 on path score.
A31: • | B31: New shelves the list missed: Desk Organizers, Pencil Cases & Pouches, Classroom Decor, Storage Baskets (all Tier 1), plus desk-setup items and office decor in Tier 2.
A32: • | B32: v2 vs v1: added the Hero lens. Clocks and Desk Pads drop from Tier 2 to Tier 3 because they are Non-Hero; Tier 2 now holds 23 shelves.
A34: Suggested sequencing
A35: 1. | B35: Wave 1a (Staples data already in hand): Accent & Waiting Room Chairs, Desk Lamps, Planners, Water Bottles, Backpacks, Lunch Bags & Boxes: 2 Heroes (extend) and 4 Probable Heroes (build).
A36: 2. | B36: Wave 1b (needs a Staples leaf scrape first): Desk Organizers, Pencil Cases & Pouches, Classroom Decor, Storage Baskets.
A37: 3. | B37: Keep Office Chairs as a control shelf (Hero, PROTECT): it shows the safety gate correctly rejecting look-alikes of core 1P chairs.
A38: 4. | B38: Before the run: collect competitor listings per 'Competitor Fit' (primary first), confirm the depth scores, and ask Pat for a Staples sales / margin rank to replace the Hero proxies.
A40: How to read this workbook
B41: Segment Map | C41: One picture: every shelf placed as Hero, Probable Hero or Non-Hero.
B42: Your List Review | C42: Verdict on each of the 9 initial items, their segment mix, and exact L3/L4 drill-downs.
B43: Recommended Paths | C43: Tier 1 + Tier 2 shelves with segment, play, archetype hypotheses, 1P watch-outs, moments and where to look.
B44: Selection Criteria | C44: Gates, weights, segmentation proxies, cut-offs and plays (editable yellow cells).
B45: Path Scorecard | C45: All 67 candidate shelves with gates, segment, scores, rank, tier and play (formulas).
...

Sheet Segment Map
A1: Segment map: Staples strength vs market attractiveness
A2: Picture = snapshot at default inputs (labelled). The Excel chart further down is live: it moves when you edit inputs or cut-offs.
B47: How to read it: right of the dashed line = Hero (Staples is already strong); top-left = Probable Hero (the market loves it, Staples is not yet a destination); bottom-left = Non-Hero.
B48: Plays: Hero shelves get EXTEND (add style extensions only) or PROTECT (keep the marketplace out, e.g. Office Chairs, Pens); Probable Heroes get BUILD (fill the gap with marketplace sellers); Non-Heroes are held.
B49: Tier 1 mixes both growth stories: Heroes to extend (Planners, Desk Organizers, Backpacks, Classroom Decor) and Probable Heroes to build (Water Bottles, Accent Chairs, Desk Lamps, Pencil Cases, Lunch, Storage Baskets).

Sheet Your List Review
A1: Review of the initial 9-item list, with exact L3/L4 drill-downs and their Hero segments
A2: Table 1 = verdict per item; column I shows that most L2s mix Hero, Probable Hero and Non-Hero shelves, which is why segmenting at L2 misleads. Table 2 = the drill-down paths.
A4: # | B4: Your item | C4: Your competitor | D4: Exact Staples node(s) | E4: Verdict | F4: What the research says | G4: Competitor view | H4: Recommended primary / secondary | I4: Segment mix of its L3/L4 paths (live)
A5: 1 | B5: Chairs & Seating | C5: Wayfair | D5: Furniture > Chairs & Seating | E5: KEEP: strongest item on the list | F5: Core-adjacent furniture with 14 leaves. The pilot already proved the method here (Accent & Waiting Room, Benches, Bar Stools). The 2026 'resimercial' return-to-office trend supports design-led seating. | G5: Wayfair is the right primary (depth + aesthetic, already scraped). Add Amazon as secondary for the recruitable seller pool and the value tier. | H5: Wayfair / Amazon | I5: ="Hero "&COUNTIFS('Hero Segmentation'!$C$5:$C$71,"1. Chairs & Seating",'Hero Segmentation'!$Q$5:$Q$71,"Hero",'Hero Segmentation'!$S$5:$S$71,"<>Parked (gate)")&CHAR(10)&"Probable Hero "&COUNTIFS('Hero Segmentation'!$C$5:$C$71,"1. Chairs & Seating",'Hero Segmentation'!$Q$5:$Q$71,"Probable Hero",'Hero Segmentation'!$S$5:$S$71,"<>Parked (gate)")&CHAR(10)&"Non-Hero "&COUNTIFS('Hero Segmentation'!$C$5:$C$71,"1. Chairs & Seating",'Hero Segmentation'!$Q$5:$Q$71,"Non-Hero",'Hero Segmentation'!$S$5:$S$71,"<>Parked (gate)")&CHAR(10)&"Parked "&COUNTIFS('Hero Segmentation'!$C$5:$C$71,"1. Chairs & Seating",'Hero Segmentation'!$S$5:$S$71,"Parked (gate)") -> Hero 1 Probable Hero 5 Non-Hero 2 Parked 0
A6: 2 | B6: Desks | C6: Wayfair | D6: Furniture > Desks | E6: KEEP, narrow to Office Desks | F6: Office Desks is the real shelf (1,501 items) and splits cleanly by Staples' own type facet. Sit & Stand is spec-led (motors, frames), so design gaps are smaller and cannibalisation risk is higher. | G6: Wayfair primary for Office Desks. If Sit & Stand is kept, Amazon should lead it (FlexiSpot / VIVO-type sellers). | H6: Wayfair / Amazon | I6: ="Hero "&COUNTIFS('Hero Segmentation'!$C$5:$C$71,"2. Desks",'Hero Segmentation'!$Q$5:$Q$71,"Hero",'Hero Segmentation'!$S$5:$S$71,"<>Parked (gate)")&CHAR(10)&"Probable Hero "&COUNTIFS('Hero Segmentation'!$C$5:$C$71,"2. Desks",'Hero Segmentation'!$Q$5:$Q$71,"Probable Hero",'Hero Segmentation'!$S$5:$S$71,"<>Parked (gate)")&CHAR(10)&"Non-Hero "&COUNTIFS('Hero Segmentation'!$C$5:$C$71,"2. Desks",'Hero Segmentation'!$Q$5:$Q$71,"Non-Hero",'Hero Segmentation'!$S$5:$S$71,"<>Parked (gate)")&CHAR(10)&"Parked "&COUNTIFS('Hero Segmentation'!$C$5:$C$71,"2. Desks",'Hero Segmentation'!$S$5:$S$71,"Parked (gate)") -> Hero 2 Probable Hero 0 Non-Hero 1 Parked 0
A7: 3 | B7: Lamps & Lighting | C7: Wayfair | D7: Furniture > Lamps & Lighting | E7: KEEP | F7: The purest aesthetic category in the core catalogue, and Staples SKUs are already in hand for desk, table and floor lamps. | G7: Wayfair is right. Amazon as secondary for Desk Lamps; Target for Table and Floor Lamps. | H7: Wayfair / Amazon or Target | I7: ="Hero "&COUNTIFS('Hero Segmentation'!$C$5:$C$71,"3. Lamps & Lighting",'Hero Segmentation'!$Q$5:$Q$71,"Hero",'Hero Segmentation'!$S$5:$S$71,"<>Parked (gate)")&CHAR(10)&"Probable Hero "&COUNTIFS('Hero Segmentation'!$C$5:$C$71,"3. Lamps & Lighting",'Hero Segmentation'!$Q$5:$Q$71,"Probable Hero",'Hero Segmentation'!$S$5:$S$71,"<>Parked (gate)")&CHAR(10)&"Non-Hero "&COUNTIFS('Hero Segmentation'!$C$5:$C$71,"3. Lamps & Lighting",'Hero Segmentation'!$Q$5:$Q$71,"Non-Hero",'Hero Segmentation'!$S$5:$S$71,"<>Parked (gate)")&CHAR(10)&"Parked "&COUNTIFS('Hero Segmentation'!$C$5:$C$71,"3. Lamps & Lighting",'Hero Segmentation'!$S$5:$S$71,"Parked (gate)") -> Hero 0 Probable Hero 3 Non-Hero 0 Parked 0
A8: 4 | B8: Rugs | C8: Wayfair | D8: Decor > Rugs (L2 leaf, no L3/L4 under it) | E8: PARK: fails the granularity gate | F8: There is nothing to drill into: 'Decor > Rugs' is a single L2 leaf of 804 items. Rugs are also residential decor, the weakest link to Staples' work and school mission. | G8: Wayfair would be the right competitor if a rug story is ever needed. For a decor story at L3/L4, use Storage Baskets (Tier 1) or Faux Plants / Frames (Tier 2). | H8: n/a | I8: ="Hero "&COUNTIFS('Hero Segmentation'!$C$5:$C$71,"4. Rugs",'Hero Segmentation'!$Q$5:$Q$71,"Hero",'Hero Segmentation'!$S$5:$S$71,"<>Parked (gate)")&CHAR(10)&"Probable Hero "&COUNTIFS('Hero Segmentation'!$C$5:$C$71,"4. Rugs",'Hero Segmentation'!$Q$5:$Q$71,"Probable Hero",'Hero Segmentation'!$S$5:$S$71,"<>Parked (gate)")&CHAR(10)&"Non-Hero "&COUNTIFS('Hero Segmentation'!$C$5:$C$71,"4. Rugs",'Hero Segmentation'!$Q$5:$Q$71,"Non-Hero",'Hero Segmentation'!$S$5:$S$71,"<>Parked (gate)")&CHAR(10)&"Parked "&COUNTIFS('Hero Segmentation'!$C$5:$C$71,"4. Rugs",'Hero Segmentation'!$S$5:$S$71,"Parked (gate)") -> Hero 0 Probable Hero 0 Non-Hero 0 Parked 1
A9: 5 | B9: Fitness Equipment | C9: Amazon | D9: Fitness > Fitness Equipment > Fitness Machines > Fitness Machines (the only leaf) | E9: REFOCUS as 'active workstation': Tier 3 | F9: Fitness is not a Staples destination: one leaf, 43 items, and not in the header nav. The only defensible angle is under-desk walking pads and desk bikes sold next to sit-stand desks. Bulky, low attach. | G9: Amazon is the right primary; Dick's Sporting Goods as secondary. | H9: Amazon / Dick's | I9: ="Hero "&COUNTIFS('Hero Segmentation'!$C$5:$C$71,"5. Fitness Equipment",'Hero Segmentation'!$Q$5:$Q$71,"Hero",'Hero Segmentation'!$S$5:$S$71,"<>Parked (gate)")&CHAR(10)&"Probable Hero "&COUNTIFS('Hero Segmentation'!$C$5:$C$71,"5. Fitness Equipment",'Hero Segmentation'!$Q$5:$Q$71,"Probable Hero",'Hero Segmentation'!$S$5:$S$71,"<>Parked (gate)")&CHAR(10)&"Non-Hero "&COUNTIFS('Hero Segmentation'!$C$5:$C$71,"5. Fitness Equipment",'Hero Segmentation'!$Q$5:$Q$71,"Non-Hero",'Hero Segmentation'!$S$5:$S$71,"<>Parked (gate)")&CHAR(10)&"Parked "&COUNTIFS('Hero Segmentation'!$C$5:$C$71,"5. Fitness Equipment",'Hero Segmentation'!$S$5:$S$71,"Parked (gate)") -> Hero 0 Probable Hero 1 Non-Hero 0 Parked 0
A10: 6 | B10: Backpacks & Bags | C10: Scheels | D10: Bags, Backpacks & Luggage > Backpacks & Laptop Bags (+ Totes & Handbags, Briefcases & Padfolios) | E10: KEEP the category, CHANGE the competitor | F10: A strong BTS anchor (85% of parents buy a backpack, Circana). But Scheels' depth is technical, hunting and outdoor packs, far from Staples' student and commuter shopper, so the method would mostly return OFF-BRAND archetypes. Scheels is also regional and blocks scraping. | G10: Amazon primary (breadth, recruitable sellers), Target secondary (lifestyle styles; JanSport sells via Target Plus). Keep Scheels only as an outdoor style reference. | H10: Amazon / Target | I10: ="Hero "&COUNTIFS('Hero Segmentation'!$C$5:$C$71,"6. Backpacks & Bags",'Hero Segmentation'!$Q$5:$Q$71,"Hero",'Hero Segmentation'!$S$5:$S$71,"<>Parked (gate)")&CHAR(10)&"Probable Hero "&COUNTIFS('Hero Segmentation'!$C$5:$C$71,"6. Backpacks & Bags",'Hero Segmentation'!$Q$5:$Q$71,"Probable Hero",'Hero Segmentation'!$S$5:$S$71,"<>Parked (gate)")&CHAR(10)&"Non-Hero "&COUNTIFS('Hero Segmentation'!$C$5:$C$71,"6. Backpacks & Bags",'Hero Segmentation'!$Q$5:$Q$71,"Non-Hero",'Hero Segmentation'!$S$5:$S$71,"<>Parked (gate)")&CHAR(10)&"Parked "&COUNTIFS('Hero Segmentation'!$C$5:$C$71,"6. Backpacks & Bags",'Hero Segmentation'!$S$5:$S$71,"Parked (gate)") -> Hero 1 Probable Hero 3 Non-Hero 0 Parked 1
A11: 7 | B11: Hydration & Drinkware | C11: Scheels | D11: Coffee, Water & Snacks > Water & Beverages > Water Bottles, Tumblers & Travel Mugs | E11: KEEP: a top-3 path | F11: The Staples node is an L3 under Coffee, Water & Snacks (there is no 'Hydration' node). 463 items, already in the sample. The kitchen 'Drinkware & Glassware' leaf has only 15 items and fails the baseline gate. | G11: Dick's primary (same brand depth as Scheels, but national); Target secondary (exclusive colourways, closest shopper). Scheels is an acceptable alternate. | H11: Dick's / Target | I11: ="Hero "&COUNTIFS('Hero Segmentation'!$C$5:$C$71,"7. Hydration & Drinkware",'Hero Segmentation'!$Q$5:$Q$71,"Hero",'Hero Segmentation'!$S$5:$S$71,"<>Parked (gate)")&CHAR(10)&"Probable Hero "&COUNTIFS('Hero Segmentation'!$C$5:$C$71,"7. Hydration & Drinkware",'Hero Segmentation'!$Q$5:$Q$71,"Probable Hero",'Hero Segmentation'!$S$5:$S$71,"<>Parked (gate)")&CHAR(10)&"Non-Hero "&COUNTIFS('Hero Segmentation'!$C$5:$C$71,"7. Hydration & Drinkware",'Hero Segmentation'!$Q$5:$Q$71,"Non-Hero",'Hero Segmentation'!$S$5:$S$71,"<>Parked (gate)")&CHAR(10)&"Parked "&COUNTIFS('Hero Segmentation'!$C$5:$C$71,"7. Hydration & Drinkware",'Hero Segmentation'!$S$5:$S$71,"Parked (gate)") -> Hero 0 Probable Hero 1 Non-Hero 0 Parked 1
A12: 8 | B12: Labels & Packaging Accessories | C12: Michaels | D12: Office Supplies > Labels (L2 leaf) · Party Supplies > Wrapping Supplies · Retail Store Supplies > Retail Packaging | E12: REFRAME | F12: 'Labels' is an L2 leaf of 11,493 Avery-type labels: no L3/L4, commodity, core 1P. Gift wrap and gift bags now overlap the Party City partner assortment on Staples.com (Apr-2026). Michaels has little depth in business labels or small-business packaging. | G12: Reframe as small-business packaging & labelling: Amazon primary, Uline secondary. For Label Makers: Amazon + Michaels (Cricut). | H12: Amazon / Uline | I12: ="Hero "&COUNTIFS('Hero Segmentation'!$C$5:$C$71,"8. Labels & Packaging Accessories",'Hero Segmentation'!$Q$5:$Q$71,"Hero",'Hero Segmentation'!$S$5:$S$71,"<>Parked (gate)")&CHAR(10)&"Probable Hero "&COUNTIFS('Hero Segmentation'!$C$5:$C$71,"8. Labels & Packaging Accessories",'Hero Segmentation'!$Q$5:$Q$71,"Probable Hero",'Hero Segmentation'!$S$5:$S$71,"<>Parked (gate)")&CHAR(10)&"Non-Hero "&COUNTIFS('Hero Segmentation'!$C$5:$C$71,"8. Labels & Packaging Accessories",'Hero Segmentation'!$Q$5:$Q$71,"Non-Hero",'Hero Segmentation'!$S$5:$S$71,"<>Parked (gate)")&CHAR(10)&"Parked "&COUNTIFS('Hero Segmentation'!$C$5:$C$71,"8. Labels & Packaging Accessories",'Hero Segmentation'!$S$5:$S$71,"Parked (gate)") -> Hero 2 Probable Hero 1 Non-Hero 0 Parked 3
A13: 9 | B13: Planning & Craft Organization | C13: Michaels | D13: Office Supplies > Calendars & Planners · Arts & Crafts > Scrapbooking / Crafting · Office Supplies > Storage & Organization | E13: KEEP, split in two | F13: Two different shopper missions in one bucket. Planning is the #1 path overall (Michaels' Happy Planner ecosystem vs Staples' dated planners). Craft organization is thin at Staples (66 items) and works better as general organization. | G13: Planning: Amazon and Michaels are a near-tie (Amazon edges it on seller recruitability): run both, with Michaels as the enthusiast-format benchmark. Organization: Target + Amazon, with Container Store as the style benchmark. | H13: Amazon / Michaels; Target / Amazon | I13: ="Hero "&COUNTIFS('Hero Segmentation'!$C$5:$C$71,"9. Planning & Craft Organization",'Hero Segmentation'!$Q$5:$Q$71,"Hero",'Hero Segmentation'!$S$5:$S$71,"<>Parked (gate)")&CHAR(10)&"Probable Hero "&COUNTIFS('Hero Segmentation'!$C$5:$C$71,"9. Planning & Craft Organization",'Hero Segmentation'!$Q$5:$Q$71,"Probable Hero",'Hero Segmentation'!$S$5:$S$71,"<>Parked (gate)")&CHAR(10)&"Non-Hero "&COUNTIFS('Hero Segmentation'!$C$5:$C$71,"9. Planning & Craft Organization",'Hero Segmentation'!$Q$5:$Q$71,"Non-Hero",'Hero Segmentation'!$S$5:$S$71,"<>Parked (gate)")&CHAR(10)&"Parked "&COUNTIFS('Hero Segmentation'!$C$5:$C$71,"9. Planning & Craft Organization",'Hero Segmentation'!$S$5:$S$71,"Parked (gate)") -> Hero 3 Probable Hero 3 Non-Hero 1 Parked 0
A15: Table 2. Drill-down L3/L4 paths for each item (exact nav-tree paths; tier, score and competitors are live)
A16: # | B16: Path ID | C16: Staples path (exact) | D16: Level | E16: Category ID | F16: Staples items | G16: Hero segment | H16: Marketplace play | I16: Tier | J16: Score | K16: Primary / Secondary competitor | L16: Role in PoC
A17: 1 | B17: P04 | C17: Furniture > Chairs & Seating > Accent & Waiting Room Chairs | D17: 3 | E17: CL70203 | F17: 229 | G17: =INDEX('Path Scorecard'!$Q$5:$Q$71,MATCH($E17,'Path Scorecard'!$H$5:$H$71,0)) -> Probable Hero | H17: =INDEX('Path Scorecard'!$AC$5:$AC$71,MATCH($E17,'Path Scorecard'!$H$5:$H$71,0)) -> BUILD | I17: =INDEX('Path Scorecard'!$AB$5:$AB$71,MATCH($E17,'Path Scorecard'!$H$5:$H$71,0)) -> Tier 1 | J17: =INDEX('Path Scorecard'!$Z$5:$Z$71,MATCH($E17,'Path Scorecard'!$H$5:$H$71,0)) -> 89 | K17: =INDEX('Path Scorecard'!$AE$5:$AE$71,MATCH($E17,'Path Scorecard'!$H$5:$H$71,0))&" / "&INDEX('Path Scorecard'!$AF$5:$AF$71,MATCH($E17,'Path Scorecard'!$H$5:$H$71,0)) -> Wayfair / Amazon | L17: PoC wave 1
A18: 1 | B18: P25 | C18: Furniture > Chairs & Seating > Sofas & Benches > Benches & Beam Seating | D18: 4 | E18: CL163750 | F18: 49 | G18: =INDEX('Path Scorecard'!$Q$5:$Q$71,MATCH($E18,'Path Scorecard'!$H$5:$H$71,0)) -> Probable Hero | H18: =INDEX('Path Scorecard'!$AC$5:$AC$71,MATCH($E18,'Path Scorecard'!$H$5:$H$71,0)) -> BUILD | I18: =INDEX('Path Scorecard'!$AB$5:$AB$71,MATCH($E18,'Path Scorecard'!$H$5:$H$71,0)) -> Tier 2 | J18: =INDEX('Path Scorecard'!$Z$5:$Z$71,MATCH($E18,'Path Scorecard'!$H$5:$H$71,0)) -> 75 | K18: =INDEX('Path Scorecard'!$AE$5:$AE$71,MATCH($E18,'Path Scorecard'!$H$5:$H$71,0))&" / "&INDEX('Path Scorecard'!$AF$5:$AF$71,MATCH($E18,'Path Scorecard'!$H$5:$H$71,0)) -> Wayfair / Amazon | L18: Wave 2 / swap-in
A19: 1 | B19: P30 | C19: Furniture > Chairs & Seating > Stools & Ottomans > Counter & Bar Stools | D19: 4 | E19: CL166182 | F19: 617 | G19: =INDEX('Path Scorecard'!$Q$5:$Q$71,MATCH($E19,'Path Scorecard'!$H$5:$H$71,0)) -> Probable Hero | H19: =INDEX('Path Scorecard'!$AC$5:$AC$71,MATCH($E19,'Path Scorecard'!$H$5:$H$71,0)) -> BUILD | I19: =INDEX('Path Scorecard'!$AB$5:$AB$71,MATCH($E19,'Path Scorecard'!$H$5:$H$71,0)) -> Tier 2 | J19: =INDEX('Path Scorecard'!$Z$5:$Z$71,MATCH($E19,'Path Scorecard'!$H$5:$H$71,0)) -> 73 | K19: =INDEX('Path Scorecard'!$AE$5:$AE$71,MATCH($E19,'Path Scorecard'!$H$5:$H$71,0))&" / "&INDEX('Path Scorecard'!$AF$5:$AF$71,MATCH($E19,'Path Scorecard'!$H$5:$H$71,0)) -> Wayfair / Amazon | L19: Wave 2 / swap-in
A20: 1 | B20: P28 | C20: Furniture > Chairs & Seating > Breakroom & Dining Chairs | D20: 3 | E20: CL166181 | F20: 75 | G20: =INDEX('Path Scorecard'!$Q$5:$Q$71,MATCH($E20,'Path Scorecard'!$H$5:$H$71,0)) -> Probable Hero | H20: =INDEX('Path Scorecard'!$AC$5:$AC$71,MATCH($E20,'Path Scorecard'!$H$5:$H$71,0)) -> BUILD | I20: =INDEX('Path Scorecard'!$AB$5:$AB$71,MATCH($E20,'Path Scorecard'!$H$5:$H$71,0)) -> Tier 2 | J20: =INDEX('Path Scorecard'!$Z$5:$Z$71,MATCH($E20,'Path Scorecard'!$H$5:$H$71,0)) -> 74 | K20: =INDEX('Path Scorecard'!$AE$5:$AE$71,MATCH($E20,'Path Scorecard'!$H$5:$H$71,0))&" / "&INDEX('Path Scorecard'!$AF$5:$AF$71,MATCH($E20,'Path Scorecard'!$H$5:$H$71,0)) -> Wayfair / Amazon | L20: Wave 2 / swap-in
A21: 1 | B21: P36 | C21: Furniture > Chairs & Seating > Stools & Ottomans > Ottomans | D21: 4 | E21: CL161807 | F21: 64 | G21: =INDEX('Path Scorecard'!$Q$5:$Q$71,MATCH($E21,'Path Scorecard'!$H$5:$H$71,0)) -> Probable Hero | H21: =INDEX('Path Scorecard'!$AC$5:$AC$71,MATCH($E21,'Path Scorecard'!$H$5:$H$71,0)) -> BUILD | I21: =INDEX('Path Scorecard'!$AB$5:$AB$71,MATCH($E21,'Path Scorecard'!$H$5:$H$71,0)) -> Tier 3 | J21: =INDEX('Path Scorecard'!$Z$5:$Z$71,MATCH($E21,'Path Scorecard'!$H$5:$H$71,0)) -> 69 | K21: =INDEX('Path Scorecard'!$AE$5:$AE$71,MATCH($E21,'Path Scorecard'!$H$5:$H$71,0))&" / "&INDEX('Path Scorecard'!$AF$5:$AF$71,MATCH($E21,'Path Scorecard'!$H$5:$H$71,0)) -> Wayfair / Amazon | L21: Backlog
A22: 1 | B22: P48 | C22: Furniture > Chairs & Seating > Office Chairs | D22: 3 | E22: CL166253 | F22: 1008 | G22: =INDEX('Path Scorecard'!$Q$5:$Q$71,MATCH($E22,'Path Scorecard'!$H$5:$H$71,0)) -> Hero | H22: =INDEX('Path Scorecard'!$AC$5:$AC$71,MATCH($E22,'Path Scorecard'!$H$5:$H$71,0)) -> PROTECT | I22: =INDEX('Path Scorecard'!$AB$5:$AB$71,MATCH($E22,'Path Scorecard'!$H$5:$H$71,0)) -> Tier 3 | J22: =INDEX('Path Scorecard'!$Z$5:$Z$71,MATCH($E22,'Path Scorecard'!$H$5:$H$71,0)) -> 65 | K22: =INDEX('Path Scorecard'!$AE$5:$AE$71,MATCH($E22,'Path Scorecard'!$H$5:$H$71,0))&" / "&INDEX('Path Scorecard'!$AF$5:$AF$71,MATCH($E22,'Path Scorecard'!$H$5:$H$71,0)) -> Wayfair / Amazon (control shelf) | L22: Control shelf (Hero, PROTECT): shows the safety gate rejecting core-1P look-alikes
A23: 1 | B23: P55 | C23: Furniture > Chairs & Seating > Kids Seating | D23: 3 | E23: CL210316 | F23: 147 | G23: =INDEX('Path Scorecard'!$Q$5:$Q$71,MATCH($E23,'Path Scorecard'!$H$5:$H$71,0)) -> Non-Hero | H23: =INDEX('Path Scorecard'!$AC$5:$AC$71,MATCH($E23,'Path Scorecard'!$H$5:$H$71,0)) -> HOLD | I23: =INDEX('Path Scorecard'!$AB$5:$AB$71,MATCH($E23,'Path Scorecard'!$H$5:$H$71,0)) -> Tier 3 | J23: =INDEX('Path Scorecard'!$Z$5:$Z$71,MATCH($E23,'Path Scorecard'!$H$5:$H$71,0)) -> 59 | K23: =INDEX('Path Scorecard'!$AE$5:$AE$71,MATCH($E23,'Path Scorecard'!$H$5:$H$71,0))&" / "&INDEX('Path Scorecard'!$AF$5:$AF$71,MATCH($E23,'Path Scorecard'!$H$5:$H$71,0)) -> Wayfair / Target | L23: Backlog
A24: 1 | B24: P58 | C24: Furniture > Chairs & Seating > Gaming Chairs | D24: 3 | E24: CL210317 | F24: 87 | G24: =INDEX('Path Scorecard'!$Q$5:$Q$71,MATCH($E24,'Path Scorecard'!$H$5:$H$71,0)) -> Non-Hero | H24: =INDEX('Path Scorecard'!$AC$5:$AC$71,MATCH($E24,'Path Scorecard'!$H$5:$H$71,0)) -> HOLD | I24: =INDEX('Path Scorecard'!$AB$5:$AB$71,MATCH($E24,'Path Scorecard'!$H$5:$H$71,0)) -> Tier 3 | J24: =INDEX('Path Scorecard'!$Z$5:$Z$71,MATCH($E24,'Path Scorecard'!$H$5:$H$71,0)) -> 50 | K24: =INDEX('Path Scorecard'!$AE$5:$AE$71,MATCH($E24,'Path Scorecard'!$H$5:$H$71,0))&" / "&INDEX('Path Scorecard'!$AF$5:$AF$71,MATCH($E24,'Path Scorecard'!$H$5:$H$71,0)) -> Best Buy / Amazon | L24: Backlog
A25: 2 | B25: P13 | C25: Furniture > Desks > Office Desks | D25: 3 | E25: CL210795 | F25: 1501 | G25: =INDEX('Path Scorecard'!$Q$5:$Q$71,MATCH($E25,'Path Scorecard'!$H$5:$H$71,0)) -> Hero | H25: =INDEX('Path Scorecard'!$AC$5:$AC$71,MATCH($E25,'Path Scorecard'!$H$5:$H$71,0)) -> EXTEND | I25: =INDEX('Path Scorecard'!$AB$5:$AB$71,MATCH($E25,'Path Scorecard'!$H$5:$H$71,0)) -> Tier 2 | J25: =INDEX('Path Scorecard'!$Z$5:$Z$71,MATCH($E25,'Path Scorecard'!$H$5:$H$71,0)) -> 81 | K25: =INDEX('Path Scorecard'!$AE$5:$AE$71,MATCH($E25,'Path Scorecard'!$H$5:$H$71,0))&" / "&INDEX('Path Scorecard'!$AF$5:$AF$71,MATCH($E25,'Path Scorecard'!$H$5:$H$71,0)) -> Wayfair / Amazon | L25: Wave 2 / swap-in
A26: 2 | B26: P47 | C26: Furniture > Desks > Sit & Stand Desks | D26: 3 | E26: CL215523 | F26: 576 | G26: =INDEX('Path Scorecard'!$Q$5:$Q$71,MATCH($E26,'Path Scorecard'!$H$5:$H$71,0)) -> Hero | H26: =INDEX('Path Scorecard'!$AC$5:$AC$71,MATCH($E26,'Path Scorecard'!$H$5:$H$71,0)) -> PROTECT | I26: =INDEX('Path Scorecard'!$AB$5:$AB$71,MATCH($E26,'Path Scorecard'!$H$5:$H$71,0)) -> Tier 3 | J26: =INDEX('Path Scorecard'!$Z$5:$Z$71,MATCH($E26,'Path Scorecard'!$H$5:$H$71,0)) -> 66 | K26: =INDEX('Path Scorecard'!$AE$5:$AE$71,MATCH($E26,'Path Scorecard'!$H$5:$H$71,0))&" / "&INDEX('Path Scorecard'!$AF$5:$AF$71,MATCH($E26,'Path Scorecard'!$H$5:$H$71,0)) -> Amazon / Wayfair | L26: Backlog
A27: 2 | B27: P57 | C27: Furniture > Desks > Desk Components & Hutches > Hutches | D27: 4 | E27: CL353865 | F27: 77 | G27: =INDEX('Path Scorecard'!$Q$5:$Q$71,MATCH($E27,'Path Scorecard'!$H$5:$H$71,0)) -> Non-Hero | H27: =INDEX('Path Scorecard'!$AC$5:$AC$71,MATCH($E27,'Path Scorecard'!$H$5:$H$71,0)) -> HOLD | I27: =INDEX('Path Scorecard'!$AB$5:$AB$71,MATCH($E27,'Path Scorecard'!$H$5:$H$71,0)) -> Tier 3 | J27: =INDEX('Path Scorecard'!$Z$5:$Z$71,MATCH($E27,'Path Scorecard'!$H$5:$H$71,0)) -> 52 | K27: =INDEX('Path Scorecard'!$AE$5:$AE$71,MATCH($E27,'Path Scorecard'!$H$5:$H$71,0))&" / "&INDEX('Path Scorecard'!$AF$5:$AF$71,MATCH($E27,'Path Scorecard'!$H$5:$H$71,0)) -> Wayfair / Amazon | L27: Backlog
A28: 3 | B28: P05 | C28: Furniture > Lamps & Lighting > Desk Lamps | D28: 3 | E28: CL167867 | F28: 210 | G28: =INDEX('Path Scorecard'!$Q$5:$Q$71,MATCH($E28,'Path Scorecard'!$H$5:$H$71,0)) -> Probable Hero | H28: =INDEX('Path Scorecard'!$AC$5:$AC$71,MATCH($E28,'Path Scorecard'!$H$5:$H$71,0)) -> BUILD | I28: =INDEX('Path Scorecard'!$AB$5:$AB$71,MATCH($E28,'Path Scorecard'!$H$5:$H$71,0)) -> Tier 1 | J28: =INDEX('Path Scorecard'!$Z$5:$Z$71,MATCH($E28,'Path Scorecard'!$H$5:$H$71,0)) -> 86 | K28: =INDEX('Path Scorecard'!$AE$5:$AE$71,MATCH($E28,'Path Scorecard'!$H$5:$H$71,0))&" / "&INDEX('Path Scorecard'!$AF$5:$AF$71,MATCH($E28,'Path Scorecard'!$H$5:$H$71,0)) -> Wayfair / Amazon | L28: PoC wave 1
... A53: 9 | B53: P34 | C53: Office Supplies > Storage & Organization > Storage Bins | D53: 3 | E53: CL354710 | F53: 660 | G53: =INDEX('Path Scorecard'!$Q$5:$Q$71,MATCH($E53,'Path Scorecard'!$H$5:$H$71,0)) -> Hero | H53: =INDEX('Path Scorecard'!$AC$5:$AC$71,MATCH($E53,'Path Scorecard'!$H$5:$H$71,0)) -> EXTEND | I53: =INDEX('Path Scorecard'!$AB$5:$AB$71,MATCH($E53,'Path Scorecard'!$H$5:$H$71,0)) -> Tier 2 | J53: =INDEX('Path Scorecard'!$Z$5:$Z$71,MATCH($E53,'Path Scorecard'!$H$5:$H$71,0)) -> 72 | K53: =INDEX('Path Scorecard'!$AE$5:$AE$71,MATCH($E53,'Path Scorecard'!$H$5:$H$71,0))&" / "&INDEX('Path Scorecard'!$AF$5:$AF$71,MATCH($E53,'Path Scorecard'!$H$5:$H$71,0)) -> Target / Amazon | L53: Wave 2 / swap-in

Sheet Recommended Paths
A1: Recommended L3/L4 paths: Tier 1 (PoC wave 1) and Tier 2 (wave 2 / swap-ins)
A2: Rows are in default-score order. Segment, play, score, tier, rank and competitors are live lookups; the narrative reflects the research at default inputs.
A4: Rank | B4: Tier | C4: Hero segment | D4: Marketplace play | E4: Score | F4: Staples path (exact) | G4: Level | H4: Category ID | I4: Staples items | J4: SKUs in hand | K4: Fast-start | L4: Primary competitor | M4: Secondary competitor | N4: Why this path | O4: Archetypes we expect to find (hypotheses) | P4: 1P watch-out (cannibalisation) | Q4: Commercial moment | R4: Why the room will relate | S4: Where to look on the competitors | T4: Staples URL
A5: =INDEX('Path Scorecard'!$AA$5:$AA$71,MATCH($H5,'Path Scorecard'!$H$5:$H$71,0)) -> 1 | B5: =INDEX('Path Scorecard'!$AB$5:$AB$71,MATCH($H5,'Path Scorecard'!$H$5:$H$71,0)) -> Tier 1 | C5: =INDEX('Path Scorecard'!$Q$5:$Q$71,MATCH($H5,'Path Scorecard'!$H$5:$H$71,0)) -> Hero | D5: =INDEX('Path Scorecard'!$AC$5:$AC$71,MATCH($H5,'Path Scorecard'!$H$5:$H$71,0)) -> EXTEND | E5: =INDEX('Path Scorecard'!$Z$5:$Z$71,MATCH($H5,'Path Scorecard'!$H$5:$H$71,0)) -> 95 | F5: Office Supplies > Calendars & Planners > Planners & Personal Organizers | G5: 3 | H5: CL166388 | I5: 1037 | J5: 1016 | K5: =INDEX('Path Scorecard'!$AD$5:$AD$71,MATCH($H5,'Path Scorecard'!$H$5:$H$71,0)) -> Yes | L5: =INDEX('Path Scorecard'!$AE$5:$AE$71,MATCH($H5,'Path Scorecard'!$H$5:$H$71,0)) -> Amazon | M5: =INDEX('Path Scorecard'!$AF$5:$AF$71,MATCH($H5,'Path Scorecard'!$H$5:$H$71,0)) -> Michaels | N5: Staples' deepest stationery shelf (1,037 items) is dated-planner led (Blue Sky, At-A-Glance). Enthusiast formats (disc-bound, undated, sticker-ready, wellness) live at Michaels and Amazon. | O5: Disc-bound customisable planners; undated goal & wellness planners; pastel/floral teacher & student planners; vegan-leather premium planners ($30-60). | P5: Dated 12-month planners incl. the Sincerely Jules exclusive: add other formats, not look-alikes. | Q5: Jan-2027 New Year planning; Jul-Aug 2027 academic planners. | R5: Staples launched Sincerely Jules for Blue Sky in Jun-2026. This shows the next step beyond one influencer line. | S5: Amazon: Planners, Refills & Covers (breadth + recruitable sellers). Michaels: Papercraft > Planners (The Happy Planner + companion accessories); near-tie with Amazon. | T5: https://www.staples.com/Planners-Personal-Organizers/cat_CL166388
A6: =INDEX('Path Scorecard'!$AA$5:$AA$71,MATCH($H6,'Path Scorecard'!$H$5:$H$71,0)) -> 2 | B6: =INDEX('Path Scorecard'!$AB$5:$AB$71,MATCH($H6,'Path Scorecard'!$H$5:$H$71,0)) -> Tier 1 | C6: =INDEX('Path Scorecard'!$Q$5:$Q$71,MATCH($H6,'Path Scorecard'!$H$5:$H$71,0)) -> Hero | D6: =INDEX('Path Scorecard'!$AC$5:$AC$71,MATCH($H6,'Path Scorecard'!$H$5:$H$71,0)) -> EXTEND | E6: =INDEX('Path Scorecard'!$Z$5:$Z$71,MATCH($H6,'Path Scorecard'!$H$5:$H$71,0)) -> 91 | F6: Office Supplies > Desk Organizers & Accessories > Desk Organizers | G6: 3 | H6: CL140991 | I6: 342 | J6: 0 | K6: =INDEX('Path Scorecard'!$AD$5:$AD$71,MATCH($H6,'Path Scorecard'!$H$5:$H$71,0)) | L6: =INDEX('Path Scorecard'!$AE$5:$AE$71,MATCH($H6,'Path Scorecard'!$H$5:$H$71,0)) -> Target | M6: =INDEX('Path Scorecard'!$AF$5:$AF$71,MATCH($H6,'Path Scorecard'!$H$5:$H$71,0)) -> Amazon | N6: Staples' 342 organizers are mostly black mesh and utility. Target (Brightroom) and Container Store sell coordinated desk collections in acrylic, bamboo, marble, linen and pastel. | O6: Clear acrylic modular sets; warm-wood / bamboo sets; pastel & neutral 'aesthetic desk' collections; turntable caddies. | P6: Black mesh sets (Staples brand, Officemate). | Q6: January 'get organized' season; BTS desk & dorm refresh. | R6: Desk organization is a header-nav Staples staple and a low-ticket attach to every paper and pen basket. | S6: Target: Brightroom desk organization + Target Plus brands. Amazon: Desk Organizers. Container Store: Office > Desktop Collections (style benchmark). | T6: https://www.staples.com/Desk-Organizers/cat_CL140991
A7: =INDEX('Path Scorecard'!$AA$5:$AA$71,MATCH($H7,'Path Scorecard'!$H$5:$H$71,0)) -> 2 | B7: =INDEX('Path Scorecard'!$AB$5:$AB$71,MATCH($H7,'Path Scorecard'!$H$5:$H$71,0)) -> Tier 1 | C7: =INDEX('Path Scorecard'!$Q$5:$Q$71,MATCH($H7,'Path Scorecard'!$H$5:$H$71,0)) -> Probable Hero | D7: =INDEX('Path Scorecard'!$AC$5:$AC$71,MATCH($H7,'Path Scorecard'!$H$5:$H$71,0)) -> BUILD | E7: =INDEX('Path Scorecard'!$Z$5:$Z$71,MATCH($H7,'Path Scorecard'!$H$5:$H$71,0)) -> 91 | F7: Coffee, Water & Snacks > Water & Beverages > Water Bottles, Tumblers & Travel Mugs | G7: 3 | H7: CL354650 | I7: 463 | J7: 462 | K7: =INDEX('Path Scorecard'!$AD$5:$AD$71,MATCH($H7,'Path Scorecard'!$H$5:$H$71,0)) -> Yes | L7: =INDEX('Path Scorecard'!$AE$5:$AE$71,MATCH($H7,'Path Scorecard'!$H$5:$H$71,0)) -> Dick's Sporting Goods | M7: =INDEX('Path Scorecard'!$AF$5:$AF$71,MATCH($H7,'Path Scorecard'!$H$5:$H$71,0)) -> Target | N7: Staples carries 463 desk-use items. Specialists sell full colourways, lids, sizes and accessories from Owala, Stanley, YETI, HydroJug and BruMate. | O7: Sip/chug hybrid bottles; 40 oz handle tumblers in seasonal colourways; kids' 12-16 oz school bottles; lids, boots & straw accessories. | P7: Stanley / Hydro Flask SKUs Staples already sells: gap is colourway & size, not the same SKU. | Q7: BTS-2027 (Jul-Sep); Q4 gifting; January hydration resolutions. | R7: Everyone in the room knows the Stanley / Owala craze. | S7: Dick's: Drinkware / Sport Water Bottles. Target: water bottles & tumblers incl. exclusive colourways. | T7: https://www.staples.com/Water-Bottles-Tumblers-Travel-Mugs/cat_CL354650
A8: =INDEX('Path Scorecard'!$AA$5:$AA$71,MATCH($H8,'Path Scorecard'!$H$5:$H$71,0)) -> 4 | B8: =INDEX('Path Scorecard'!$AB$5:$AB$71,MATCH($H8,'Path Scorecard'!$H$5:$H$71,0)) -> Tier 1 | C8: =INDEX('Path Scorecard'!$Q$5:$Q$71,MATCH($H8,'Path Scorecard'!$H$5:$H$71,0)) -> Probable Hero | D8: =INDEX('Path Scorecard'!$AC$5:$AC$71,MATCH($H8,'Path Scorecard'!$H$5:$H$71,0)) -> BUILD | E8: =INDEX('Path Scorecard'!$Z$5:$Z$71,MATCH($H8,'Path Scorecard'!$H$5:$H$71,0)) -> 89 | F8: Furniture > Chairs & Seating > Accent & Waiting Room Chairs | G8: 3 | H8: CL70203 | I8: 229 | J8: 199 | K8: =INDEX('Path Scorecard'!$AD$5:$AD$71,MATCH($H8,'Path Scorecard'!$H$5:$H$71,0)) -> Yes | L8: =INDEX('Path Scorecard'!$AE$5:$AE$71,MATCH($H8,'Path Scorecard'!$H$5:$H$71,0)) -> Wayfair | M8: =INDEX('Path Scorecard'!$AF$5:$AF$71,MATCH($H8,'Path Scorecard'!$H$5:$H$71,0)) -> Amazon | N8: The original 'White Chair' shelf. Pilot (Sep-2026): 5 recommended archetypes, 2 Strong; 94% high-confidence mapping. | O8: Boucle / curved barrel chairs; cream & sage upholstered side chairs with wood legs; rattan & cane lounge chairs; $150-350 design tier. | P8: Black vinyl / fabric guest & reception chairs (Flash, Boss, HON). | Q8: Q1-2027 office refresh and return-to-office budgets. | R8: Pat's own example: the thesis in one picture. | S8: Wayfair: Living Room > Accent Chairs and Professional > Office Seating > Accent Chairs. Amazon: Accent Chairs. | T8: https://www.staples.com/Accent-Waiting-Room-Chairs/cat_CL70203
A9: =INDEX('Path Scorecard'!$AA$5:$AA$71,MATCH($H9,'Path Scorecard'!$H$5:$H$71,0)) -> 5 | B9: =INDEX('Path Scorecard'!$AB$5:$AB$71,MATCH($H9,'Path Scorecard'!$H$5:$H$71,0)) -> Tier 1 | C9: =INDEX('Path Scorecard'!$Q$5:$Q$71,MATCH($H9,'Path Scorecard'!$H$5:$H$71,0)) -> Probable Hero | D9: =INDEX('Path Scorecard'!$AC$5:$AC$71,MATCH($H9,'Path Scorecard'!$H$5:$H$71,0)) -> BUILD | E9: =INDEX('Path Scorecard'!$Z$5:$Z$71,MATCH($H9,'Path Scorecard'!$H$5:$H$71,0)) -> 86 | F9: Furniture > Lamps & Lighting > Desk Lamps | G9: 3 | H9: CL167867 | I9: 210 | J9: 195 | K9: =INDEX('Path Scorecard'!$AD$5:$AD$71,MATCH($H9,'Path Scorecard'!$H$5:$H$71,0)) -> Yes | L9: =INDEX('Path Scorecard'!$AE$5:$AE$71,MATCH($H9,'Path Scorecard'!$H$5:$H$71,0)) -> Wayfair | M9: =INDEX('Path Scorecard'!$AF$5:$AF$71,MATCH($H9,'Path Scorecard'!$H$5:$H$71,0)) -> Amazon | N9: 210 Staples items, mostly LED task lamps. Wayfair sells mushroom, pleated, rechargeable and sculptural lamps that sit between task light and decor. | O9: Mushroom / dome lamps; pleated-shade & ceramic-base lamps; rechargeable cordless lamps; brass & warm-wood architect lamps. | P9: LED task lamps with USB ports: Staples' core. | Q9: Q1-2027 home-office refresh; BTS dorm. | R9: 2026 home-office trend reports all name better lighting and warm materials. | S9: Wayfair: Lighting > Table & Floor Lamps > Desk Lamps (+ Teen Desk Lamps). Amazon: Desk Lamps. | T9: https://www.staples.com/Desk-Lamps/cat_CL167867
A10: =INDEX('Path Scorecard'!$AA$5:$AA$71,MATCH($H10,'Path Scorecard'!$H$5:$H$71,0)) -> 5 | B10: =INDEX('Path Scorecard'!$AB$5:$AB$71,MATCH($H10,'Path Scorecard'!$H$5:$H$71,0)) -> Tier 1 | C10: =INDEX('Path Scorecard'!$Q$5:$Q$71,MATCH($H10,'Path Scorecard'!$H$5:$H$71,0)) -> Probable Hero | D10: =INDEX('Path Scorecard'!$AC$5:$AC$71,MATCH($H10,'Path Scorecard'!$H$5:$H$71,0)) -> BUILD | E10: =INDEX('Path Scorecard'!$Z$5:$Z$71,MATCH($H10,'Path Scorecard'!$H$5:$H$71,0)) -> 86 | F10: Office Supplies > Writing Supplies & Instruments > Pencil Accessories > Pencil Cases & Pouches | G10: 4 | H10: CL141253 | I10: 107 | J10: 0 | K10: =INDEX('Path Scorecard'!$AD$5:$AD$71,MATCH($H10,'Path Scorecard'!$H$5:$H$71,0)) | L10: =INDEX('Path Scorecard'!$AE$5:$AE$71,MATCH($H10,'Path Scorecard'!$H$5:$H$71,0)) -> Amazon | M10: =INDEX('Path Scorecard'!$AF$5:$AF$71,MATCH($H10,'Path Scorecard'!$H$5:$H$71,0)) -> Target | N10: 107 Staples items. The pencil pouch is the first 'aesthetic' purchase in the BTS basket, at under $20. | O10: Large-capacity multi-layer pouches (Japanese style); clear / jelly pouches; corduroy & quilted pouches; kawaii & character cases. | P10: Staples' own Recess Club pouches: extend beyond them, don't duplicate. | Q10: BTS-2027 (Jul-Sep). | R10: Staples' Recess Club / Jellygram exclusives (BTS 2026) already prove the demand. | S10: Amazon: Pencil Cases. Target: pencil cases & pouches. JetPens: Pencil Cases (style benchmark). | T10: https://www.staples.com/Pencil-Cases-Pouches/cat_CL141253
A11: =INDEX('Path Scorecard'!$AA$5:$AA$71,MATCH($H11,'Path Scorecard'!$H$5:$H$71,0)) -> 5 | B11: =INDEX('Path Scorecard'!$AB$5:$AB$71,MATCH($H11,'Path Scorecard'!$H$5:$H$71,0)) -> Tier 1 | C11: =INDEX('Path Scorecard'!$Q$5:$Q$71,MATCH($H11,'Path Scorecard'!$H$5:$H$71,0)) -> Hero | D11: =INDEX('Path Scorecard'!$AC$5:$AC$71,MATCH($H11,'Path Scorecard'!$H$5:$H$71,0)) -> EXTEND | E11: =INDEX('Path Scorecard'!$Z$5:$Z$71,MATCH($H11,'Path Scorecard'!$H$5:$H$71,0)) -> 86 | F11: Bags, Backpacks & Luggage > Backpacks & Laptop Bags > Backpacks | G11: 3 | H11: CL142745 | I11: 585 | J11: 542 | K11: =INDEX('Path Scorecard'!$AD$5:$AD$71,MATCH($H11,'Path Scorecard'!$H$5:$H$71,0)) -> Yes | L11: =INDEX('Path Scorecard'!$AE$5:$AE$71,MATCH($H11,'Path Scorecard'!$H$5:$H$71,0)) -> Amazon | M11: =INDEX('Path Scorecard'!$AF$5:$AF$71,MATCH($H11,'Path Scorecard'!$H$5:$H$71,0)) -> Target | N11: 585 Staples items, laptop & commuter led. 85% of parents bought a backpack for BTS; lifestyle backpacks grew 3% in 2025 (Circana). | O11: Corduroy / soft-aesthetic backpacks; Scandinavian-minimal daypacks; mini backpacks; personalisable patch & pin packs. | P11: Laptop backpacks (SwissGear, Targus): watch cannibalisation here. | Q11: BTS-2027. | R11: JanSport now sells on Target Plus, the curated-marketplace peer Pat can point to. | S11: Amazon: Backpacks. Target: Backpacks (incl. JanSport on Target Plus). | T11: https://www.staples.com/Backpacks/cat_CL142745
A12: =INDEX('Path Scorecard'!$AA$5:$AA$71,MATCH($H12,'Path Scorecard'!$H$5:$H$71,0)) -> 5 | B12: =INDEX('Path Scorecard'!$AB$5:$AB$71,MATCH($H12,'Path Scorecard'!$H$5:$H$71,0)) -> Tier 1 | C12: =INDEX('Path Scorecard'!$Q$5:$Q$71,MATCH($H12,'Path Scorecard'!$H$5:$H$71,0)) -> Probable Hero | D12: =INDEX('Path Scorecard'!$AC$5:$AC$71,MATCH($H12,'Path Scorecard'!$H$5:$H$71,0)) -> BUILD | E12: =INDEX('Path Scorecard'!$Z$5:$Z$71,MATCH($H12,'Path Scorecard'!$H$5:$H$71,0)) -> 86 | F12: Bags, Backpacks & Luggage > Totes & Handbags > Lunch Bags & Boxes | G12: 3 | H12: CL165124 | I12: 404 | J12: 406 | K12: =INDEX('Path Scorecard'!$AD$5:$AD$71,MATCH($H12,'Path Scorecard'!$H$5:$H$71,0)) -> Yes | L12: =INDEX('Path Scorecard'!$AE$5:$AE$71,MATCH($H12,'Path Scorecard'!$H$5:$H$71,0)) -> Amazon | M12: =INDEX('Path Scorecard'!$AF$5:$AF$71,MATCH($H12,'Path Scorecard'!$H$5:$H$71,0)) -> Target | N12: 404 Staples items. Bento compartments, stainless and leak-proof designs lead BTS and work-lunch search. | O12: Bento compartment boxes (kids & adult); neutral / vegan-leather insulated lunch totes; stainless & glass meal-prep sets. | P12: Basic insulated lunch bags Staples already stocks. | Q12: BTS-2027; January 'bring lunch to the office' resolutions. | R12: BTS is Pat's named seasonal anchor and lunch is on every parent's list. | S12: Amazon: Lunch Boxes & Bags. Target: lunch boxes & bags (Bentgo, Stasher, owned brands). | T12: https://www.staples.com/Lunch-Bags-Boxes/cat_CL165124
A13: =INDEX('Path Scorecard'!$AA$5:$AA$71,MATCH($H13,'Path Scorecard'!$H$5:$H$71,0)) -> 5 | B13: =INDEX('Path Scorecard'!$AB$5:$AB$71,MATCH($H13,'Path Scorecard'!$H$5:$H$71,0)) -> Tier 1 | C13: =INDEX('Path Scorecard'!$Q$5:$Q$71,MATCH($H13,'Path Scorecard'!$H$5:$H$71,0)) -> Hero | D13: =INDEX('Path Scorecard'!$AC$5:$AC$71,MATCH($H13,'Path Scorecard'!$H$5:$H$71,0)) -> EXTEND | E13: =INDEX('Path Scorecard'!$Z$5:$Z$71,MATCH($H13,'Path Scorecard'!$H$5:$H$71,0)) -> 86 | F13: School Supplies > Teacher Supplies > Classroom Decorations > Decorative Accents & Board Sets | G13: 4 | H13: CL219245 | I13: 607 | J13: 0 | K13: =INDEX('Path Scorecard'!$AD$5:$AD$71,MATCH($H13,'Path Scorecard'!$H$5:$H$71,0)) | L13: =INDEX('Path Scorecard'!$AE$5:$AE$71,MATCH($H13,'Path Scorecard'!$H$5:$H$71,0)) -> Amazon | M13: =INDEX('Path Scorecard'!$AF$5:$AF$71,MATCH($H13,'Path Scorecard'!$H$5:$H$71,0)) -> Oriental Trading | N13: 607 Staples items. Teachers self-fund about $895 a year and buy decor as coordinated themes (boho, calm, pastel). | O13: Boho / neutral theme sets; calm-corner & SEL decor; pastel bulletin-board kits; plant & nature themes. | P13: Existing bulletin-board sets: compare theme coverage, not SKU swaps. | Q13: BTS-2027 classroom set-up (Jul-Aug); Teacher Appreciation Week (May). | R13: Teachers are a Staples loyalty segment (teacher coupon, teacher lists). | S13: Amazon: Classroom Decorations. Oriental Trading: Teaching Supplies > Classroom Decorations. Michaels: Teacher Supplies. | T13: https://www.staples.com/Decorative-Accents-Board-Sets/cat_CL219245
A14: =INDEX('Path Scorecard'!$AA$5:$AA$71,MATCH($H14,'Path Scorecard'!$H$5:$H$71,0)) -> 10 | B14: =INDEX('Path Scorecard'!$AB$5:$AB$71,MATCH($H14,'Path Scorecard'!$H$5:$H$71,0)) -> Tier 1 | C14: =INDEX('Path Scorecard'!$Q$5:$Q$71,MATCH($H14,'Path Scorecard'!$H$5:$H$71,0)) -> Probable Hero | D14: =INDEX('Path Scorecard'!$AC$5:$AC$71,MATCH($H14,'Path Scorecard'!$H$5:$H$71,0)) -> BUILD | E14: =INDEX('Path Scorecard'!$Z$5:$Z$71,MATCH($H14,'Path Scorecard'!$H$5:$H$71,0)) -> 85 | F14: Office Supplies > Storage & Organization > Storage Baskets | G14: 3 | H14: CL354705 | I14: 95 | J14: 0 | K14: =INDEX('Path Scorecard'!$AD$5:$AD$71,MATCH($H14,'Path Scorecard'!$H$5:$H$71,0)) | L14: =INDEX('Path Scorecard'!$AE$5:$AE$71,MATCH($H14,'Path Scorecard'!$H$5:$H$71,0)) -> Wayfair | M14: =INDEX('Path Scorecard'!$AF$5:$AF$71,MATCH($H14,'Path Scorecard'!$H$5:$H$71,0)) -> Target | N14: Only 95 Staples items, while Wayfair has dedicated Woven Baskets, Decorative Bins and Fabric Baskets nodes. Pure style-led storage. | O14: Seagrass / water-hyacinth woven baskets; felt & linen fabric bins; lined wire baskets; lidded decorative boxes. | P14: Plastic bins sit in the sister node: keep baskets style-led. | Q14: January 'get organized' season. | R14: Organization is a January ritual every retailer promotes. | S14: Wayfair: Organization > Storage Containers & Drawers (Woven Baskets, Decorative Bins, Fabric Baskets). Target: Brightroom baskets. | T14: https://www.staples.com/Storage-Baskets/cat_CL354705
A15: =INDEX('Path Scorecard'!$AA$5:$AA$71,MATCH($H15,'Path Scorecard'!$H$5:$H$71,0)) -> 11 | B15: =INDEX('Path Scorecard'!$AB$5:$AB$71,MATCH($H15,'Path Scorecard'!$H$5:$H$71,0)) -> Tier 2 | C15: =INDEX('Path Scorecard'!$Q$5:$Q$71,MATCH($H15,'Path Scorecard'!$H$5:$H$71,0)) -> Probable Hero | D15: =INDEX('Path Scorecard'!$AC$5:$AC$71,MATCH($H15,'Path Scorecard'!$H$5:$H$71,0)) -> BUILD | E15: =INDEX('Path Scorecard'!$Z$5:$Z$71,MATCH($H15,'Path Scorecard'!$H$5:$H$71,0)) -> 83 | F15: Bags, Backpacks & Luggage > Backpacks & Laptop Bags > Laptop Sleeves & Cases | G15: 3 | H15: CL219256 | I15: 300 | J15: 265 | K15: =INDEX('Path Scorecard'!$AD$5:$AD$71,MATCH($H15,'Path Scorecard'!$H$5:$H$71,0)) | L15: =INDEX('Path Scorecard'!$AE$5:$AE$71,MATCH($H15,'Path Scorecard'!$H$5:$H$71,0)) -> Amazon | M15: =INDEX('Path Scorecard'!$AF$5:$AF$71,MATCH($H15,'Path Scorecard'!$H$5:$H$71,0)) -> Target | N15: 300 Staples items. A sleeve is a low-ticket attach to every laptop sale. | O15: Felt & vegan-leather sleeves; pastel / pattern sleeves with pouch; puffer sleeves. | P15: Black Targus / Case Logic sleeves. | Q15: BTS; laptop-attach all year. | R15: Directly serves Pat's '1-2 extra items per checkout'. | S15: Amazon: Laptop Sleeves. Target: laptop sleeves. | T15: https://www.staples.com/Laptop-Sleeves-Cases/cat_CL219256
A16: =INDEX('Path Scorecard'!$AA$5:$AA$71,MATCH($H16,'Path Scorecard'!$H$5:$H$71,0)) -> 12 | B16: =INDEX('Path Scorecard'!$AB$5:$AB$71,MATCH($H16,'Path Scorecard'!$H$5:$H$71,0)) -> Tier 2 | C16: =INDEX('Path Scorecard'!$Q$5:$Q$71,MATCH($H16,'Path Scorecard'!$H$5:$H$71,0)) -> Probable Hero | D16: =INDEX('Path Scorecard'!$AC$5:$AC$71,MATCH($H16,'Path Scorecard'!$H$5:$H$71,0)) -> BUILD | E16: =INDEX('Path Scorecard'!$Z$5:$Z$71,MATCH($H16,'Path Scorecard'!$H$5:$H$71,0)) -> 82 | F16: Bags, Backpacks & Luggage > Briefcases & Padfolios > Totes & Handbags | G16: 3 | H16: CL160451 | I16: 173 | J16: 166 | K16: =INDEX('Path Scorecard'!$AD$5:$AD$71,MATCH($H16,'Path Scorecard'!$H$5:$H$71,0)) | L16: =INDEX('Path Scorecard'!$AE$5:$AE$71,MATCH($H16,'Path Scorecard'!$H$5:$H$71,0)) -> Amazon | M16: =INDEX('Path Scorecard'!$AF$5:$AF$71,MATCH($H16,'Path Scorecard'!$H$5:$H$71,0)) -> Target | N16: 173 Staples items. The work tote is the lifestyle version of the briefcase. | O16: Structured work totes with laptop sleeve; neoprene totes; vegan-leather commuter totes. | P16: Briefcases & padfolios (Samsonite, Solo). | Q16: Q1 return-to-office; graduation gifting. | R16: The 'White Chair' of bags. | S16: Amazon: work totes. Target: tote bags. | T16: https://www.staples.com/Totes-Handbags/cat_CL160451
... A37: =INDEX('Path Scorecard'!$AA$5:$AA$71,MATCH($H37,'Path Scorecard'!$H$5:$H$71,0)) -> 34 | B37: =INDEX('Path Scorecard'!$AB$5:$AB$71,MATCH($H37,'Path Scorecard'!$H$5:$H$71,0)) -> Tier 2 | C37: =INDEX('Path Scorecard'!$Q$5:$Q$71,MATCH($H37,'Path Scorecard'!$H$5:$H$71,0)) -> Probable Hero | D37: =INDEX('Path Scorecard'!$AC$5:$AC$71,MATCH($H37,'Path Scorecard'!$H$5:$H$71,0)) -> BUILD | E37: =INDEX('Path Scorecard'!$Z$5:$Z$71,MATCH($H37,'Path Scorecard'!$H$5:$H$71,0)) -> 72 | F37: Furniture > Boards & Easels > Calendar & In-Out Boards | G37: 3 | H37: CL142105 | I37: 63 | J37: 0 | K37: =INDEX('Path Scorecard'!$AD$5:$AD$71,MATCH($H37,'Path Scorecard'!$H$5:$H$71,0)) | L37: =INDEX('Path Scorecard'!$AE$5:$AE$71,MATCH($H37,'Path Scorecard'!$H$5:$H$71,0)) -> Amazon | M37: =INDEX('Path Scorecard'!$AF$5:$AF$71,MATCH($H37,'Path Scorecard'!$H$5:$H$71,0)) -> Wayfair | N37: 63 Staples items. | O37: Acrylic dry-erase wall calendars; glass monthly planners; felt calendar boards. | P37: In/out boards. | Q37: January. | R37: Pairs with planners & calendars. | S37: Amazon: acrylic calendars. Wayfair: Memo Boards. | T37: https://www.staples.com/Calendar-In-Out-Boards/cat_CL142105

Sheet Selection Criteria
A1: Selection criteria, weights and thresholds
A2: Yellow cells with blue text are editable. Every score, rank, tier and competitor role in the workbook recalculates from them.
A4: A. Hard gates: a path must pass all four to be scored
A5: Code | B5: Gate | C5: Rule | D5: Why it matters
A6: G1 | B6: Granularity | C6: The node is an L3 or L4 in the Staples navigation tree (Level 3 or 4). | D6: Your feedback: L2 is too coarse. The gap must be readable on one shelf.
A7: G2 | B7: Brand authority | C7: The node sits on a Staples work / school / small-business mission (not mis-shelved or leisure). | D7: Pat: build momentum 'without straying too far from Staples' brand authority'.
A8: G3 | B8: Staples baseline | C8: Staples lists at least the minimum item count (threshold in section C). | D8: Needs a nearest-Staples-family comparison and a share baseline.
A9: G4 | B9: No partner conflict | C9: No Staples strategic partner already owns the assortment on Staples.com. | D9: Party City (Apr-2026) now supplies party décor, gift bags & wrap: marketplace adds would compete with a partner.
A11: B. Weighted path criteria: each scored 1-5, weighted score scaled to 0-100
A12: Code | B12: Criterion | C12: What it measures | D12: Scores 5 when | E12: Scores 1 when | F12: Weight
A13: C1 | B13: Design & lifestyle variance ('White Chair' test) | C13: Do shoppers choose on colour, material, style or 'vibe' rather than spec? | D13: Style drives the choice; many aesthetic archetypes exist | E13: Pure spec / commodity | F13: 20
A14: C2 | B14: Competitor depth advantage | C14: How much wider the best competitor's assortment is on this shelf | D14: Best competitor is several times wider, with archetypes Staples lacks | E14: Parity with Staples | F14: 15
A15: C3 | B15: 1P protection (low cannibalisation) | C15: Can design variants be added without substituting Staples' core best-sellers? | D15: Design variants clearly distinct from the 1P core | E15: Direct substitute of core 1P | F15: 15
A16: C4 | B16: Core-adjacency & shopper mission | C16: Same work, school or small-business mission as Staples' core | D16: Sits on the core Staples mission | E16: Residential or leisure mission | F16: 15
A17: C5 | B17: Basket attach & quick-win economics | C17: Parcel-shippable, lower ticket, attaches to core baskets (Pat: +1-2 items per checkout) | D17: Under ~$50, parcel, frequent attach | E17: Oversize freight, considered purchase | F17: 10
A18: C6 | B18: Business familiarity & story | C18: Would the Staples room recognise it instantly (header nav, Staples' own recent moves, visible trend)? | D18: Header-nav shelf + Staples' own recent move or a famous trend | E18: Obscure shelf | F18: 10
A19: C7 | B19: Commercial moment | C19: Peaks in the Q1-2027 window or BTS-2027 (Pat's seasonal anchor) | D19: Peaks in Jan-Mar or Jul-Sep 2027 | E19: No clear moment | F19: 5
A20: C8 | B20: Data readiness | C20: Staples SKUs already in hand + competitor already scraped or reachable | D20: Both sides in hand / reachable | E20: Neither side available | F20: 10
E21: Total weight | F21: =SUM(F13:F20) -> 100
A23: C. Thresholds
A24: Code | B24: Parameter | C24: Value | D24: Note
A25: T1 | B25: Tier 1 cut-off (score >=) | C25: 84 | D25: Tier 1 = PoC wave 1 (10 paths at default weights).
A26: T2 | B26: Tier 2 cut-off (score >=) | C26: 72 | D26: Tier 2 = wave 2 / swap-ins (25 paths at default weights).
A27: G3 | B27: Minimum Staples items on the leaf | C27: 20 | D27: Feeds gate G3.
A28: FS | B28: Fast-start: min Staples SKUs already in the sample | C28: 100 | D28: Tier 1 paths above this can start without a new Staples scrape.
A30: D. Competitor selection criteria: each competitor scored 1-5 per path
A31: Code | B31: Criterion | C31: What it measures | D31: Scores 5 when | E31: Scores 1 when | F31: Weight
A32: K1 | B32: Assortment depth on this shelf | C32: Breadth of the competitor's range on the mapped node | D32: Several times Staples' range, many sub-types | E32: Similar or smaller than Staples | F32: 30
